Workbook
Name FATESTCD: CODELIST!#REF!
Name OLE_LINK73: CONTENT!$B$3
Name VSTEST: CODELIST!#REF!
Name VSTESTCD: CODELIST!$I$219
Name VSTPT: CODELIST!$I$231
Name VSTPTNUM: CODELIST!$I$239

Sheet CONTENT
A1: SDTM Domain Mapping Specifications
A3: 方案编号 | B3: XXXXX
A4: SDTM 版本 | B4: 3.2
A6: SDTM Domain | B6: SDTM 数据集描述 | C6: SDTM 数据集结构 | D6: 程序名称 | E6: 常规观测分类 | F6: 数据来源 | G6: 关键变量 | H6: 排序变量 | I6: 提取规则 | J6: Documentation | K6: RunOrder
A7: AE | B7: 不良事件 | C7: 每个受试者每例次不良事件一条记录 | D7: ae.sas | E7: 事件 | F7: AE, AE_DE, SDTM.DM, SDTM.SE, SDTM.CM, SDTM.PR | G7: STUDYID, USUBJID, AESPID, AEDECOD, AETERM, AESTDTC, AEENDTC, AETOXGR | H7: STUDYID, USUBJID, AESPID, AEDECOD, AETERM, AESTDTC, AEENDTC, AETOXGR | I7: ALL | K7: 10
A8: CE | B8: 临床事件 | C8: 每个受试者每例次临床事件一条记录 | D8: ce.sas | E8: 事件 | F8: XXXX | G8: STUDYID, USUBJID, CETERM, CESTDTC | H8: STUDYID, USUBJID, CETERM, CESTDTC | I8: XXXX | K8: 11
A9: CM | B9: 既往与合并用药 | C9: 每个受试者每次给药或每个用法一条记录 | D9: cm.sas | E9: 干预 | F9: DH, DH_DE, CM, AD, SDTM.DM, SDTM.SE | G9: STUDYID, USUBJID, CMCAT, CMSCAT, CMSPID, CMTRT, CMSTDTC, CMENDTC | H9: STUDYID, USUBJID, CMCAT, CMSCAT, CMSPID, CMTRT, CMSTDTC, CMENDTC | I9: [RAW.DH]: 当DH.YN='1';[RAW.CM]: 当CM.YN='1';[RAW.AD]: 当AD.YN='1'. | K9: 12
A10: CO | B10: 备注 | C10: 每个受试者每条备注一条记录 | D10: co.sas | E10: 特殊用途 | F10: XXXX | G10: STUDYID, USUBJID, COSEQ | H10: STUDYID, USUBJID, COSEQ | I10: XXXX | K10: 13
A11: DA | B11: 药物收发记录 | C11: 每个受试者每个药物收发情况一条记录 | D11: da.sas | E11: 发现 | F11: XXXX | G11: STUDYID, USUBJID, DATESTCD, DADTC | H11: STUDYID, USUBJID, DATESTCD, DADTC | I11: XXXX | K11: 14
A12: DD | B12: 死亡详情 | C12: 每个受试者每个发现一条记录 | D12: dd.sas | E12: 发现 | F12: XXXX | G12: STUDYID, USUBJID, DDTESTCD, DDDTC | H12: STUDYID, USUBJID, DDTESTCD, DDDTC | I12: XXXX | K12: 15
A13: DM | B13: 人口学 | C13: 每个受试者一条记录 | D13: dm.sas | E13: 特殊用途 | F13: DM, EX, ICF, SV, RAND, PE, LB, TCT, TC_DE, VS1, VS1_DE, VS1_OTH, VS2, ECG, EG, ECOG, EG_DE, EOT, ADAE_DE, IMT, IM_DE, AE, SF, TUCL, VIR, TLB, NTLB, HT, WT, CCR, HCG, OT, DS, DR, SUBJECT, ADA_DE, NL_DE, NTL_DE, OBT, OB_DE, OEA, PKD_DE, PKND_DE, TL_DE, UNSO_DE | G13: STUDYID, USUBJID | H13: STUDYID, USUBJID | I13: ALL | K13: 1
A14: DS | B14: 受试者分布 | C14: 每个受试者每个完成状态或每个方案里程碑事件一条记录 | D14: ds.sas | E14: 事件 | F14: ICF, RAND, EOT, DS, SDTM.DM, SDTM.SE | G14: STUDYID, USUBJID, DSSTDTC, DSDECOD | H14: STUDYID, USUBJID, DSSTDTC, DSDECOD | I14: ALL | K14: 16
A15: DV | B15: 方案偏离 | C15: 每个受试者每例次方案偏离一条记录 | D15: dv.sas | E15: 事件 | F15: XXXX | G15: STUDYID, USUBJID, DVTERM, DVSTDTC | H15: STUDYID, USUBJID, DVTERM, DVSTDTC | I15: XXXX | K15: 17
A16: EC | B16: 暴露采集 | C16: 每个受试者每个方案规定的研究用药每个采集的用法每个情景模式一条记录 | D16: ec.sas | E16: 干预 | F16: EX, SDTM.DM | G16: STUDYID, USUBJID, ECTRT, ECSTDTC, ECENDTC | H16: STUDYID, USUBJID, ECTRT, ECSTDTC, ECENDTC | I16: ALL | K16: 18
A17: EG | B17: 心电图 | C17: 每个受试者每个访视每个时间点每次心电图每个发现一条记录 | D17: eg.sas | E17: 发现 | F17: EG, EG_DE, SDTM.DM, SDTM.SE | G17: STUDYID, USUBJID, EGTESTCD, VISITNUM, EGDTC, EGSPID | H17: STUDYID, USUBJID, EGTESTCD, VISITNUM, EGDTC, EGSPID | I17: ALL | K17: 19
A18: EX | B18: 暴露 | C18: 每个受试者每个研究药物每个用法一条记录 | D18: ex.sas | E18: 干预 | F18: EX, SDTM.DM | G18: STUDYID, USUBJID, EXTRT, EXSTDTC, EXENDTC | H18: STUDYID, USUBJID, EXTRT, EXSTDTC, EXENDTC | I18: EX.EXYN="1" | K18: 20
... A51: VS | B51: 生命体征 | C51: 每个受试者每个访视每个时间点每个生命体征测量一条记录 | D51: vs.sas | E51: 发现 | F51: VS1, VS1_DE, VS1_OTH, VS2, HT, WT, SDTM.DM, SDTM.SE | G51: STUDYID, USUBJID, VSTESTCD, VISITNUM, VSTPTNUM, VSDTC, VSSPID, VSSTRESN | H51: STUDYID, USUBJID, VSTESTCD, VISITNUM, VSTPTNUM, VSDTC, VSSPID, VSSTRESN | I51: 如果VS1.VS1YN="1"或者VS1.VS1OYN="1" | K51: 45
A52: SUPP-- | B52: 补充修饰语数据集 | C52: 每个受试者一个域一个修饰变量一条记录 | E52: 特殊用途 | G52: STUDYID, RDOMAIN, USUBJID, IDVAR, IDVARVAL, QNAM | H52: STUDYID, RDOMAIN, USUBJID, QNAM
A54: CODELIST
A56: 重要提示:
A57: (1) 请根据项目的具体情况选择合适的SDTM域，并按照需要添加相应的补充数据集(SUPP--)。蓝色斜体字体可根据项目的具体信息进行修改。
A58: (2) SDTM域必须以字母顺序列出(相应的补充数据集应该在SDTM域之后立即进行)。
A59: (3) 一个SDTM域一个表格,即使是多个数据源。
A60: (4) SDTM域必须以.xpt格式生成。
A61: (5) 每个SDTM域中，请按照项目的具体需求选择合适的变量。其中，核心类别为"必需"的变量必须保留。（注：SDTMIG3.3及以后版本对于各个域均增加了EPOCH变量，可按需添加）
A62: (6) 所有__CAT, __SCAT 和 DSDECOD变量的值都要大写。
A63: (7) 如果筛选失败受试者收集了DM信息则也要保留其数据。

Sheet Revision History
A1: Version | B1: Date | C1: Domain(s) | D1: Variable(s) | E1: Modification Details
A2: 1.0 | B2: 44897 | C2: NA | D2: NA | E2: Initial Version
A3: 1.1 | B3: 44924 | C3: T domains | D3: NA | E3: Add T domain metadata

Sheet CODELIST
A1: Control Terminology | I1: CRF
A2: Domain | B2: ID | C2: Name | D2: NCI_Codelist_Code | E2: Datatype | F2: Term | G2: NCI_Term_Code | H2: Decode | I2: CRF Term
A3: ALL | B3: ND | C3: 未查 | D3: C66789 | E3: Char | F3: 未查 | G3: C49484
A4: ALL | B4: NY | C4: 是非应答 | D4: C66742 | E4: Char | F4: N | G4: C49487 | H4: 否 | I4: 否
A5: ALL | B5: NY | C5: 是非应答 | D5: C66742 | E5: Char | F5: NA | G5: C48660 | H5: 不适用 | I5: NA
A6: ALL | B6: NY | C6: 是非应答 | D6: C66742 | E6: Char | F6: U | G6: C17998 | H6: U; UNK; 不详 | I6: 未知
A7: ALL | B7: NY | C7: 是非应答 | D7: C66742 | E7: Char | F7: Y | G7: C49488 | H7: 是 | I7: 是
A8: DM | B8: AGEU | C8: 年龄单位 | D8: C66781 | E8: Char | F8: 岁 | G8: C29848 | H8: 年
A9: DM | B9: SEX | C9: 性别 | D9: C66731 | E9: Char | F9: F | G9: C16576 | H9: 女性
A10: DM | B10: SEX | C10: 性别 | D10: C66731 | E10: Char | F10: M | G10: C20197 | H10: 男性
A11: DM | B11: RACE | C11: 种族 | D11: C74457 | E11: Char | F11: 美国印第安人或阿拉斯加原住民 | G11: C41259
A12: DM | B12: RACE | C12: 种族 | D12: C74457 | E12: Char | F12: 亚洲人 | G12: C41260 | I12: 亚裔
A13: DM | B13: RACE | C13: 种族 | D13: C74457 | E13: Char | F13: 黑种人或非裔美国人 | G13: C16352
A14: DM | B14: RACE | C14: 种族 | D14: C74457 | E14: Char | F14: 夏威夷原住民或其他太平洋岛民 | G14: C41219
A15: DM | B15: RACE | C15: 种族 | D15: C74457 | E15: Char | F15: 白种人 | G15: C41261
A16: DM | B16: ETHNIC | C16: 族群 | D16: C66790 | E16: Char | F16: 西班牙裔或拉丁裔 | G16: C17459
A17: DM | B17: ETHNIC | C17: 族群 | D17: C66790 | E17: Char | F17: 非西班牙裔或拉丁裔 | G17: C41222
A18: DM | B18: ETHNIC | C18: 族群 | D18: C66790 | E18: Char | F18: 未报告 | G18: C43234
A19: DM | B19: ETHNIC | C19: 族群 | D19: C66790 | E19: Char | F19: 不详 | G19: C17998
A20: DM | B20: ETHNIC | C20: 族群 | D20: C66790 | E20: Char | I20: 汉族
A21: DM | B21: ETHNIC | C21: 族群 | D21: C66790 | E21: Char | I21: 其他
A22: AE | B22: ACN | C22: 对研究治疗采取的措施 | D22: C66767 | E22: Char | F22: 剂量增加 | G22: C49503
A23: AE | B23: ACN | C23: 对研究治疗采取的措施 | D23: C66767 | E23: Char | F23: 无变化 | G23: C49504 | I23: 不变
A24: AE | B24: ACN | C24: 对研究治疗采取的措施 | D24: C66767 | E24: Char | F24: 给药速率降低 | G24: C150826
A25: AE | B25: ACN | C25: 对研究治疗采取的措施 | D25: C66767 | E25: Char | F25: 剂量减少 | G25: C49505 | I25: 剂量减少
A26: AE | B26: ACN | C26: 对研究治疗采取的措施 | D26: C66767 | E26: Char | F26: 暂停给药 | G26: C49501 | I26: 暂停用药
A27: AE | B27: ACN | C27: 对研究治疗采取的措施 | D27: C66767 | E27: Char | F27: 停药 | G27: C49502 | I27: 永久停药
A28: AE | B28: ACN | C28: 对研究治疗采取的措施 | D28: C66767 | E28: Char | F28: 不适用 | G28: C48660 | I28: 不适用
A29: AE | B29: ACN | C29: 对研究治疗采取的措施 | D29: C66767 | E29: Char | F29: 未知 | G29: C17998 | I29: 不详
A30: AE | B30: AESEV | C30: 不良事件严重程度 | D30: C66769 | E30: Char | F30: 轻度 | G30: C41338 | H30: 1; 1级
A31: AE | B31: AESEV | C31: 不良事件严重程度 | D31: C66769 | E31: Char | F31: 中度 | G31: C41339 | H31: 2; 2级
A32: AE | B32: AESEV | C32: 不良事件严重程度 | D32: C66769 | E32: Char | F32: 重度 | G32: C41340 | H32: 3; 3级
A33: AE | B33: OUT | C33: 事件转归 | D33: C66768 | E33: Char | F33: 死亡 | G33: C48275 | H33: 5; 死亡; 5级 | I33: 死亡
A34: AE | B34: OUT | C34: 事件转归 | D34: C66768 | E34: Char | F34: 未好转 | G34: C49494 | I34: 未好转
A35: AE | B35: OUT | C35: 事件转归 | D35: C66768 | E35: Char | F35: 痊愈 | G35: C49498 | I35: 痊愈/恢复
A36: AE | B36: OUT | C36: 事件转归 | D36: C66768 | E36: Char | F36: 痊愈有后遗症 | G36: C49495 | I36: 痊愈/恢复伴有后遗症
A37: AE | B37: OUT | C37: 事件转归 | D37: C66768 | E37: Char | F37: 好转 | G37: C49496 | I37: 好转
A38: AE | B38: OUT | C38: 事件转归 | D38: C66768 | E38: Char | F38: 不详 | G38: C17998 | H38: U; UNK; 不详 | I38: 不详
A39: ALL | B39: STENRF | C39: 与参考时间的关系 | D39: C66728 | E39: Char | F39: 之后 | G39: C38008
A40: ALL | B40: STENRF | C40: 与参考时间的关系 | D40: C66728 | E40: Char | F40: 之前 | G40: C25629
...

Sheet AE
A1: AE Domain Mapping Specifications
A2: 方案编号: | D2: =CONTENT!$B$3 -> XXXXX
A3: SDTM 版本: | D3: =CONTENT!$B$4 -> 3.2
A4: SDTM 数据集描述: | D4: =CONTENT!$B$7 -> 不良事件
A5: SDTM 数据集结构: | D5: =CONTENT!$C$7 -> 每个受试者每例次不良事件一条记录
A6: 程序名称: | D6: =CONTENT!$D$7 -> ae.sas
A7: 常规观测分类: | D7: =CONTENT!$E$7 -> 事件
A8: 数据来源: | D8: =CONTENT!$F$7 -> AE, AE_DE, SDTM.DM, SDTM.SE, SDTM.CM, SDTM.PR
A9: 关键变量: | D9: =CONTENT!$G$7 -> STUDYID, USUBJID, AESPID, AEDECOD, AETERM, AESTDTC, AEENDTC, AETOXGR
A10: 排序变量: | D10: =CONTENT!$G$7 -> STUDYID, USUBJID, AESPID, AEDECOD, AETERM, AESTDTC, AEENDTC, AETOXGR
A11: 提取规则: | D11: =CONTENT!$I$7 -> ALL
A13: 变量名称 | B13: 变量标签 | C13: 类型 | D13: 长度 | E13: 受控术语或格式 | F13: 来源 | G13: 核心类别 | H13: 转换定义 | I13: 变量类型 | J13: 变量顺序 | K13: 定义注释
A14: STUDYID | B14: 研究标识符 | C14: Char | D14: 20 | F14: 指定 | G14: 必需 | H14: QL1706-101 | I14: SDTM | J14: =ROW()-13 -> 1 | K14: 研究的唯一标识符。
A15: DOMAIN | B15: 域名缩写 | C15: Char | D15: 2 | E15: AE | F15: 指定 | G15: 必需 | H15: AE | I15: SDTM | J15: =ROW()-13 -> 2 | K15: 两字符域名缩写。
A16: USUBJID | B16: 受试者唯一标识符 | C16: Char | D16: 30 | F16: 衍生 | G16: 必需 | H16: 通过 "-" 连接 STUDYID, SITEID, SUBJID (例:QL1706-101-01-01001). | I16: SDTM | J16: =ROW()-13 -> 3 | K16: 同一产品的所有申请或递交的研究中受试者的唯一标识符。
A17: AESEQ | B17: 序号 | C17: Num | F17: 衍生 | G17: 必需 | H17: 按照变量 STUDYID, USUBJID, AESPID, AEDECOD, AETERM, AESTDTC, AEENDTC排序. 在每个USUBJID开始的时候用1开始重新编号 (循环地排序). | I17: SDTM | J17: =ROW()-13 -> 4 | K17: 给出序列号以确保域内主题序号的唯一性。可以是任何有效数字。
A18: AEGRPID | B18: 组合ID | C18: Char | D18: 25 | G18: 可有 | I18: SDTM | J18: =ROW()-13 -> 5 | K18: 用来关联域内同一个受试者的一组相关记录。
A19: AEREFID | B19: 参考ID | C19: Char | D19: 25 | G19: 可有 | I19: SDTM | J19: =ROW()-13 -> 6 | K19: 内部或外部编号,如 SAE 报告表上的序列号。
A20: AESPID | B20: 自定义标识符 | C20: Char | D20: 25 | F20: CRF Page 63 | G20: 可有 | H20: z2.格式的AE.SN | I20: SDTM | J20: =ROW()-13 -> 7 | K20: 申办者定义的标识符,可以是作为显示行标志预印刷在CRF上,或在申办者操作数据库中定义。例如:不良事件页上的行号。
A21: AETERM | B21: 不良事件报告名称 | C21: Char | D21: 200 | F21: CRF Page 63 | G21: 必需 | H21: AE.AETERM | I21: SDTM | J21: =ROW()-13 -> 8 | K21: 事件的本名。
A22: AEMODIFY | B22: 修正词 | C22: Char | D22: 200 | G22: 可有 | I22: SDTM | J22: =ROW()-13 -> 9 | K22: 如果修正了AETERM以便编码,那么AEMODIFY将包含修正后的文本。
A23: AELLT | B23: 低位语 | C23: Char | D23: 200 | E23: MedDRA | F23: 指定 | G23: 期望 | H23: 连接外部coding文件的"MedDRA编码明细"表单, 取"低位语" 通过研究中心编号, 受试者代码, 序号, 逐词术语匹配SITEID, SUBJID, SN, AETERM | I23: SDTM | J23: =ROW()-13 -> 10 | K23: 低位语的字典衍生文本描述。
A24: AELLTCD | B24: 低位语编码 | C24: Num | E24: MedDRA | F24: 指定 | G24: 期望 | H24: 连接外部coding文件的"MedDRA编码明细"表单, 取"低位语代码" 通过研究中心编号, 受试者代码, 序号, 逐词术语匹配SITEID, SUBJID, SN, AETERM | I24: SDTM | J24: =ROW()-13 -> 11 | K24: 低位语的字典衍生代码。
A25: AEDECOD | B25: 标准化名称 | C25: Char | D25: 200 | E25: MedDRA | F25: 指定 | G25: 必需 | H25: 连接外部coding文件的"MedDRA编码明细"表单, 取"首选语" 通过研究中心编号, 受试者代码, 序号, 逐词术语匹配SITEID, SUBJID, SN, AETERM | I25: SDTM | J25: =ROW()-13 -> 12 | K25: 字典衍生的AETERM或AEMODIFY的文字描述,等同于首选语(MedDRA中的PT)。申办者应该在提供用于Define.xml 外部编码列表属性映射术语的字典的名字和版本。
A26: AEPTCD | B26: 首选语编码 | C26: Num | E26: MedDRA | F26: 指定 | G26: 期望 | H26: 连接外部coding文件的"MedDRA编码明细"表单, 取"首选语代码" 通过研究中心编号, 受试者代码, 序号, 逐词术语匹配SITEID, SUBJID, SN, AETERM | I26: SDTM | J26: =ROW()-13 -> 13 | K26: 基于字典编码的首选术语。
A27: AEHLT | B27: 高位语 | C27: Char | D27: 200 | E27: MedDRA | F27: 指定 | G27: 期望 | H27: 连接外部coding文件的"MedDRA编码明细"表单, 取"高位语" 通过研究中心编号, 受试者代码, 序号, 逐词术语匹配SITEID, SUBJID, SN, AETERM | I27: SDTM | J27: =ROW()-13 -> 14 | K27: 主系统器官分类的高位语的字典衍生文本描述。
A28: AEHLTCD | B28: 高位语编码 | C28: Num | E28: MedDRA | F28: 指定 | G28: 期望 | H28: 连接外部coding文件的"MedDRA编码明细"表单, 取"高位语代码" 通过研究中心编号, 受试者代码, 序号, 逐词术语匹配SITEID, SUBJID, SN, AETERM | I28: SDTM | J28: =ROW()-13 -> 15 | K28: 主系统器官分类的高位语的字典衍生代码。
A29: AEHLGT | B29: 高位组语 | C29: Char | D29: 200 | E29: MedDRA | F29: 指定 | G29: 期望 | H29: 连接外部coding文件的"MedDRA编码明细"表单, 取"高位组语" 通过研究中心编号, 受试者代码, 序号, 逐词术语匹配SITEID, SUBJID, SN, AETERM | I29: SDTM | J29: =ROW()-13 -> 16 | K29: 主系统器官分类的高位组语的字典衍生文本描述。
A30: AEHLGTCD | B30: 高位组语编码 | C30: Num | E30: MedDRA | F30: 指定 | G30: 期望 | H30: 连接外部coding文件的"MedDRA编码明细"表单, 取"高位组语代码" 通过研究中心编号, 受试者代码, 序号, 逐词术语匹配SITEID, SUBJID, SN, AETERM | I30: SDTM | J30: =ROW()-13 -> 17 | K30: 主系统器官分类的高位组语的字典衍生代码。
A31: AECAT | B31: 类别 | C31: Char | D31: 100 | E31: * | G31: 可有 | I31: SDTM | J31: =ROW()-13 -> 18 | K31: 用来定义相关记录的类别。 例如:出血、神经精神疾病。
A32: AESCAT | B32: 子类 | C32: Char | D32: 100 | E32: * | G32: 可有 | I32: SDTM | J32: =ROW()-13 -> 19 | K32: 不良事件进一步分类。 例如:神经系统
A33: AEPRESP | B33: 预设 | C33: Char | D33: 10 | E33: (NY) | G33: 可有 | I33: SDTM | J33: =ROW()-13 -> 20 | K33: "Y"(是)值说明该不良事件为在 CRF 上预设。 自发报告的事件其值为空(即那些采集为自由文本的事件名称)
A34: AEBODSYS | B34: 系统器官分类 | C34: Char | D34: 200 | E34: * | F34: 指定 | G34: 期望 | H34: 连接外部coding文件的"MedDRA编码明细"表单, 取"系统器官分类" 通过研究中心编号, 受试者代码, 序号, 逐词术语匹配SITEID, SUBJID, SN, AETERM | I34: SDTM | J34: =ROW()-13 -> 21 | K34: 词典衍生。申办者使用系统或器官分类,源自编码编码词典(MedDRA)。当使用的词典为多轴时,如MedDRA,本变量应包含用于申办者分析与总结表格的SOC,不必是主 SOC。
A35: AEBDSYCD | B35: 系统器官分类编码 | C35: Num | E35: MedDRA | F35: 指定 | G35: 期望 | H35: 连接外部coding文件的"MedDRA编码明细"表单, 取"系统器官分类代码" 通过研究中心编号, 受试者代码, 序号, 逐词术语匹配SITEID, SUBJID, SN, AETERM | I35: SDTM | J35: =ROW()-13 -> 22 | K35: 来源于词典。申办者用于身体系统或器官分类的编码,当使用多级编码词典如MedDRA 时,本变量应包含申办者用于分析与汇总的SOC,不必是主SOC。
A36: AESOC | B36: 主系统器官分类 | C36: Char | D36: 200 | E36: MedDRA | F36: 指定 | G36: 期望 | H36: 连接外部coding文件的"MedDRA编码明细"表单, 取"系统器官分类" 通过研究中心编号, 受试者代码, 序号, 逐词术语匹配SITEID, SUBJID, SN, AETERM | I36: SDTM | J36: =ROW()-13 -> 23 | K36: 从字典中获得主要系统器官分类的编码。 假如主要系统器官分类被用于分析,将会与AEBODSYS相同。
A37: AESOCCD | B37: 主系统器官分类编码 | C37: Num | E37: MedDRA | F37: 指定 | G37: 期望 | H37: 连接外部coding文件的"MedDRA编码明细"表单, 取"系统器官分类代码" 通过研究中心编号, 受试者代码, 序号, 逐词术语匹配SITEID, SUBJID, SN, AETERM | I37: SDTM | J37: =ROW()-13 -> 24 | K37: 从字典中获得主要系统器官分类的编码。 假如主要系统器官分类被用于分析,将会与AEBDSYCD相同。
A38: AELOC | B38: 部位 | C38: Char | D38: 40 | E38: (LOC) | G38: 可有 | I38: SDTM | J38: =ROW()-13 -> 25 | K38: 描述了与事件相关的解剖学位置。 (例如: "左臂"皮疹)
A39: AESEV | B39: 严重程度 | C39: Char | D39: 10 | E39: (AESEV) | G39: 可有 | I39: SDTM | J39: =ROW()-13 -> 26 | K39: 事件的严重程度或强度。 例如:轻度、中度、重度。
A40: AESER | B40: 严重事件 | C40: Char | D40: 10 | E40: (NY) | F40: CRF Page 63 | G40: 期望 | H40: 当AE.SAEYN='1'时, AESER='是'; 当AE.SAEYN='2'时, AESER='否'. | I40: SDTM | J40: =ROW()-13 -> 27 | K40: 这是一个严重事件吗?
A41: AEACN | B41: 对研究治疗采取的措施 | C41: Char | D41: 25 | E41: (ACN) | F41: CRF Page 63 | G41: 期望 | H41: 当AE.AEACN='1'时, AEACN='不变'; 当AE.AEACN='2'时, AEACN='暂停用药'; 当AE.AEACN='3'时, AEACN='剂量减少'; 当AE.AEACN='4'时, AEACN='永久停药'; 当AE.AEACN='5'时, AEACN='不适用'; 当AE.AEACN='6'时, AEACN='不详'. | I41: SDTM | J41: =ROW()-13 -> 28 | K41: 描述了因事件而对研究治疗的改变。AEACN特别用于与研究治疗相关的。AEACNOTH用于与研究治疗剂量调整无关的措施。 ICH E2B 示例包含的值:停止用药、剂量减少、剂量增加、剂量不变、未知或不适用。
...

Sheet CE
A1: CE Domain Mapping Specifications
A2: 方案编号: | D2: =CONTENT!$B$3 -> XXXXX
A3: SDTM 版本: | D3: =CONTENT!$B$4 -> 3.2
A4: SDTM 数据集描述: | D4: =CONTENT!$B$8 -> 临床事件
A5: SDTM 数据集结构: | D5: =CONTENT!$C$8 -> 每个受试者每例次临床事件一条记录
A6: 程序名称: | D6: =CONTENT!$D$8 -> ce.sas
A7: 常规观测分类: | D7: =CONTENT!$E$8 -> 事件
A8: 数据来源: | D8: =CONTENT!$F$8 -> XXXX
A9: 关键变量: | D9: =CONTENT!$G$8 -> STUDYID, USUBJID, CETERM, CESTDTC
A10: 排序变量: | D10: =CONTENT!$H$8 -> STUDYID, USUBJID, CETERM, CESTDTC
A11: 提取规则: | D11: =CONTENT!$I$8 -> XXXX
A13: 变量名称 | B13: 变量标签 | C13: 类型 | D13: 长度 | E13: 受控术语或格式 | F13: 来源 | G13: 核心类别 | H13: 转换定义 | I13: 变量类型 | J13: 变量顺序 | K13: 定义注释
A14: STUDYID | B14: 研究标识符 | C14: Char | D14: 20 | G14: 必需 | I14: SDTM | J14: =ROW()-13 -> 1 | K14: 研究的唯一标识符。
A15: DOMAIN | B15: 域名缩写 | C15: Char | D15: 2 | E15: CE | G15: 必需 | I15: SDTM | J15: =ROW()-13 -> 2 | K15: 两字符域名缩写。
A16: USUBJID | B16: 受试者唯一标识符 | C16: Char | D16: 30 | G16: 必需 | I16: SDTM | J16: =ROW()-13 -> 3 | K16: 同一产品的所有申请或递交的研究中受试者的唯一标识符。
A17: CESEQ | B17: 序号 | C17: Num | G17: 必需 | I17: SDTM | J17: =ROW()-13 -> 4 | K17: 序列号,确保一个受试者在数据集里唯一性。可以用来连接相关记录。
A18: CEGRPID | B18: 组合ID | C18: Char | D18: 25 | G18: 可有 | I18: SDTM | J18: =ROW()-13 -> 5 | K18: 用来关联域内同一个受试者的一组相关记录。
A19: CEREFID | B19: 参考ID | C19: Char | D19: 25 | G19: 可有 | I19: SDTM | J19: =ROW()-13 -> 6 | K19: 内部或者外部的标识。
A20: CESPID | B20: 自定义标识符 | C20: Char | D20: 25 | G20: 可有 | I20: SDTM | J20: =ROW()-13 -> 7 | K20: 申办者定义的参考标识。可能是在预先印刷的 CRF 中明确的行标识,或者在申办者操作的数据库中定义的。比如, CRF页中的行号。
A21: CETERM | B21: 临床事件报告名称 | C21: Char | D21: 200 | G21: 必需 | I21: SDTM | J21: =ROW()-13 -> 8 | K21: 医疗状况或事件的术语。 一般在CRF中预先设定。
A22: CEDECOD | B22: 标准化名称 | C22: Char | D22: 200 | E22: * | G22: 可有 | I22: SDTM | J22: =ROW()-13 -> 9 | K22: 临床事件名称的受控术语。申办者应提供使用的词典名称和版本,体现在define.xml外部代码列表属性中。
A23: CECAT | B23: 类别 | C23: Char | D23: 100 | E23: * | G23: 可有 | I23: SDTM | J23: =ROW()-13 -> 10 | K23: 用于定义相关记录的分类。
A24: CESCAT | B24: 子类 | C24: Char | D24: 100 | E24: * | G24: 可有 | I24: SDTM | J24: =ROW()-13 -> 11 | K24: 状况或事件的进一步分类。
A25: CEPRESP | B25: 预设 | C25: Char | D25: 10 | E25: (NY) | G25: 可有 | I25: SDTM | J25: =ROW()-13 -> 12 | K25: 用于指明CETERM的事件是否是预先指定的。如果预先指定事件的值为Y,则自发报告事件的值为空。
A26: CEOCCUR | B26: 是否发生 | C26: Char | D26: 10 | E26: (NY) | G26: 可有 | I26: SDTM | J26: =ROW()-13 -> 13 | K26: 用于记录特定事件的请求发生时,是否当作一个临床事 件的发生。自发报告事件的值为空。
A27: CESTAT | B27: 未做状态 | C27: Char | D27: 10 | E27: (ND) | G27: 可有 | I27: SDTM | J27: =ROW()-13 -> 14 | K27: 表示未回答预先指定的列表中的问题的状态。
A28: CEREASND | B28: 未做原因 | C28: Char | D28: 200 | G28: 可有 | I28: SDTM | J28: =ROW()-13 -> 15 | K28: 描述未采集临床事件的原因。值为NOT DONE时与CESTAT一致使用。
A29: CEBODSYS | B29: 系统器官分类 | C29: Char | D29: 200 | E29: * | G29: 可有 | I29: SDTM | J29: =ROW()-13 -> 16 | K29: 来源于词典。相关事件中的身体系统和器官分类或者来自于标准分级的测量(比如,MedDRA)。 使用多轴层的词典如MedDRA时,应当包括用于申办者分析和总结表格的SOC,不一定是主SOC。
A30: CESEV | B30: 严重程度 | C30: Char | D30: 10 | E30: * | G30: 可有 | I30: SDTM | J30: =ROW()-13 -> 17 | K30: 事件的严重程度或强度。例如:轻微、中度或重度。
A31: CEDTC | B31: 采集日期/时间 | C31: Char | D31: 20 | E31: ISO 8601 | G31: 可有 | I31: SDTM | J31: =ROW()-13 -> 18
A32: CESTDTC | B32: 开始日期/时间 | C32: Char | D32: 20 | E32: ISO 8601 | G32: 可有 | I32: SDTM | J32: =ROW()-13 -> 19
A33: CEENDTC | B33: 结束日期/时间 | C33: Char | D33: 20 | E33: ISO 8601 | G33: 可有 | I33: SDTM | J33: =ROW()-13 -> 20
A34: CEDY | B34: 采集日 | C34: Num | G34: 可有 | I34: SDTM | J34: =ROW()-13 -> 21 | K34: 1、临床事件采集时候的研究日期,应用整数的天数来测量。2、计算的算法必需和在人口学中申办者定义的RFSTDTC变量相关。
A35: CESTRF | B35: 开始时间-相对参照区间 | C35: Char | D35: 20 | E35: (STENRF) | G35: 可有 | I35: SDTM | J35: =ROW()-13 -> 22 | K35: 描述与申办者定义的参照期相关的临床事件的开始。申办者定义的参照期是一段持续的时段,由确切的开始时间点和确切的结束时间点(由人口统计域中的RFSTDTC和RFENDTC表示)规定。
A36: CEENRF | B36: 结束时间-相对参照区间 | C36: Char | D36: 20 | E36: (STENRF) | G36: 可有 | I36: SDTM | J36: =ROW()-13 -> 23 | K36: 描述与申办者定义的参照期相关的临床事件的结束。申办者定义的参照期是一段持续的时段,由确切的开始时间点和确切的结束时间点(由人口统计域中的RFSTDTC和RFENDTC表示)规定。
A37: CESTRTPT | B37: 开始时间-相对参照时点 | C37: Char | D37: 20 | E37: (STENRF) | G37: 可有 | I37: SDTM | J37: =ROW()-13 -> 24 | K37: 确认观测的开始是在由变量 CESTTPT 定义的参照时间点之前或之后。
A38: CESTTPT | B38: 开始时间的参照时点 | C38: Char | D38: 100 | G38: 可有 | I38: SDTM | J38: =ROW()-13 -> 25 | K38: ISO 8601字符格式的描述或日期/时间,申办者定义的参照点。例如:"2003-12-15"或"访视 1"。
A39: CEENRTPT | B39: 结束时间-相对参照时点 | C39: Char | D39: 20 | E39: (STENRF) | G39: 可有 | I39: SDTM | J39: =ROW()-13 -> 26 | K39: 确认观测的结束是在由变量CEENTPT定义的参照时间点之前或之后。
A40: CEENTPT | B40: 结束时间的参照时点 | C40: Char | D40: 100 | G40: 可有 | I40: SDTM | J40: =ROW()-13 -> 27 | K40: ISO 8601字符格式的描述或日期/时间,申办者定义的参照点。例如:"2003-12-25"或"访视 2"。
A42: CONTENT

Sheet CM
A1: CM Domain Mapping Specifications
A2: 方案编号: | D2: =CONTENT!$B$3 -> XXXXX
A3: SDTM 版本: | D3: =CONTENT!$B$4 -> 3.2
A4: SDTM 数据集描述: | D4: =CONTENT!$B$9 -> 既往与合并用药
A5: SDTM 数据集结构: | D5: =CONTENT!$C$9 -> 每个受试者每次给药或每个用法一条记录
A6: 程序名称: | D6: =CONTENT!$D$9 -> cm.sas
A7: 常规观测分类: | D7: =CONTENT!$E$9 -> 干预
A8: 数据来源: | D8: =CONTENT!$F$9 -> DH, DH_DE, CM, AD, SDTM.DM, SDTM.SE
A9: 关键变量: | D9: =CONTENT!$G$9 -> STUDYID, USUBJID, CMCAT, CMSCAT, CMSPID, CMTRT, CMSTDTC, CMENDTC
A10: 排序变量: | D10: =CONTENT!$H$9 -> STUDYID, USUBJID, CMCAT, CMSCAT, CMSPID, CMTRT, CMSTDTC, CMENDTC
A11: 提取规则: | D11: =CONTENT!$I$9 -> [RAW.DH]: 当DH.YN='1';[RAW.CM]: 当CM.YN='1';[RAW.AD]: 当AD.YN='1'.
A13: 变量名称 | B13: 变量标签 | C13: 类型 | D13: 长度 | E13: 受控术语或格式 | F13: 来源 | G13: 核心类别 | H13: 转换定义 | I13: 变量类型 | J13: 变量顺序 | K13: 定义注释
A14: STUDYID | B14: 研究标识符 | C14: Char | D14: 20 | F14: 指定 | G14: 必需 | H14: QL1706-101 | I14: SDTM | J14: =ROW()-13 -> 1 | K14: 研究的唯一标识符。
A15: DOMAIN | B15: 域名缩写 | C15: Char | D15: 2 | E15: CM | F15: 指定 | G15: 必需 | H15: CM | I15: SDTM | J15: =ROW()-13 -> 2 | K15: 两字符域名缩写。
A16: USUBJID | B16: 受试者唯一标识符 | C16: Char | D16: 30 | F16: 衍生 | G16: 必需 | H16: 通过 "-" 连接 STUDYID, SITEID, SUBJID (例:QL1706-101-01-01001). | I16: SDTM | J16: =ROW()-13 -> 3 | K16: 同一产品的所有申请或递交的研究中受试者的唯一标识符。
A17: CMSEQ | B17: 序号 | C17: Num | F17: 衍生 | G17: 必需 | H17: 按照变量 STUDYID, USUBJID, CMCAT, CMSCAT, CMSPID, CMTRT, CMSTDTC, CMENDTC排序. 在每个USUBJID开始的时候用1开始重新编号 (循环地排序). | I17: SDTM | J17: =ROW()-13 -> 4 | K17: 序号,确保记录在域中的唯一性。可以是任何有效数字。
A18: CMGRPID | B18: 组合ID | C18: Char | D18: 25 | G18: 可有 | I18: SDTM | J18: =ROW()-13 -> 5 | K18: 用来关联域内同一个受试者的一组相关记录。
A19: CMSPID | B19: 自定义标识符 | C19: Char | D19: 25 | F19: CRF Pages 9 60 64 | G19: 可有 | H19: =HYPERLINK("#CMTRT!B1","Conversion Definition refer to CMTRT sheet") -> Conversion Definition refer to CMTRT sheet | I19: SDTM | J19: =ROW()-13 -> 6 | K19: 由申办方定义的参考数字。例如:一个预先打印在病例报告表上作为一个明确的行识别符或定义在申办方操作数据库中记录识别符的数字。例如:在伴随药物页面上的行号。
A20: CMTRT | B20: 治疗报告名称 | C20: Char | D20: 200 | F20: CRF Pages 9 60 64 | G20: 必需 | H20: =HYPERLINK("#CMTRT!B1","Conversion Definition refer to CMTRT sheet") -> Conversion Definition refer to CMTRT sheet | I20: SDTM | J20: =ROW()-13 -> 7 | K20: 药品的本名,或者被预先打印在病例报告表上或者被采集在病例报告表上。
A21: CMMODIFY | B21: 修正词 | C21: Char | D21: 200 | G21: 可有 | I21: SDTM | J21: =ROW()-13 -> 8 | K21: 如果修正了CMTRT以便编码,那么CMMODIFY会包含修正后的文本。
A22: CMDECOD | B22: 标准化名称 | C22: Char | D22: 200 | E22: * | F22: 指定 | G22: 可有 | H22: 连接外部coding文件的"WhoDrug编码明细"表单,取"首选语" 通过研究中心编号, 受试者代码, 表名称, 序号, 逐词术语匹配 [RAW.DH, RAW.DH_DE]: DH_DE.SITEID, DH_DE.SUBJID, DH_DE.PUB_TNAME, DH.SN与DH_DE.SN以'-'连接, DH_DE.DHNAME [RAW.CM]: SITEID, SUBJID, PUB_TNAME, SN, CMTRT [RAW.AD_DE]: SITEID, SUBJID, PUB_TNAME, SN, ADNAME 注:第1-200个字符 | I22: SDTM | J22: =ROW()-13 -> 9 | K22: 指的是CMTRT或CMMODIFY的标准化描述或从字典中衍生的文本描述,等同于WHO Drug中的药物通用名称,申办方应在Define.xml的外部代码列表属性中详述字典名称及版本。如果一个介入术语在字典中没有解码值,那么CMDECOD留为空值。
A23: CMCAT | B23: 类别 | C23: Char | D23: 100 | E23: * | F23: CRF Pages 9 60 64 | G23: 可有 | H23: =HYPERLINK("#CMTRT!B1","Conversion Definition refer to CMTRT sheet") -> Conversion Definition refer to CMTRT sheet | I23: SDTM | J23: =ROW()-13 -> 10 | K23: 用来定义药物/治疗的类别。例如: 既往, 伴随, 抗癌药物, 或者通常既往与合并用药。
A24: CMSCAT | B24: 子类 | C24: Char | D24: 100 | E24: * | F24: CRF Pages 9 64 | G24: 可有 | H24: =HYPERLINK("#CMTRT!B1","Conversion Definition refer to CMTRT sheet") -> Conversion Definition refer to CMTRT sheet | I24: SDTM | J24: =ROW()-13 -> 11 | K24: 药物/治疗的进一步分类。例如:化疗,激素治疗,替代疗法。
A25: CMPRESP | B25: 预设 | C25: Char | D25: 10 | E25: (NY) | G25: 可有 | I25: SDTM | J25: =ROW()-13 -> 12 | K25: 用于指示在病例报告表中是否预先定义药物,值应为"是"(Y)或"空"(null)。
A26: CMOCCUR | B26: 是否发生 | C26: Char | D26: 10 | E26: (NY) | G26: 可有 | I26: SDTM | J26: =ROW()-13 -> 13 | K26: 如果为预设药物,那么用CMOCCUR来指出是否使用了该药物。如果药物没有被预先指定,那么此变量为空值。
A27: CMSTAT | B27: 未做状态 | C27: Char | D27: 10 | E27: (ND) | G27: 可有 | I27: SDTM | J27: =ROW()-13 -> 14 | K27: 用于表明没有回答关于"预定干预是否发生"的问题。或者为 空值,或者为"未完成"。
A28: CMREASND | B28: 未做原因 | C28: Char | D28: 200 | G28: 可有 | I28: SDTM | J28: =ROW()-13 -> 15 | K28: 叙述了合并药物没有被采集的原因,如果CMSTAT是没有完成(NOT DONE)值,那么CMREASND和CMSTAT联合使用。
A29: CMINDC | B29: 适应症 | C29: Char | D29: 100 | F29: CRF Pages 9 60 | G29: 可有 | H29: =HYPERLINK("#CMTRT!B1","Conversion Definition refer to CMTRT sheet") -> Conversion Definition refer to CMTRT sheet | I29: SDTM | J29: =ROW()-13 -> 16 | K29: 指出使用或给予药物的原因。例如:恶心、高血压。
A30: CMCLAS | B30: 归类 | C30: Char | D30: 100 | E30: * | F30: 指定 | G30: 可有 | H30: 若ATC4不为空,则取ATC4; 若ATC4为空,ATC3不为空,则取ATC3; 若ATC4和ATC3为空,ATC2不为空,则取ATC2; 若ATC4,ATC3和ATC2为空,ATC1不为空,则取ATC1; 若ATC4,ATC3,ATC2,ATC1均为空展示为空. | I30: SDTM | J30: =ROW()-13 -> 17 | K30: 药物分类。可能从编码中获得。当对单独分类编码时,填充类值。如果使用字典并编码多个类别,则遵循假设 4.1.2.8.3 或删除CMCLAS。
A31: CMCLASCD | B31: 归类编码 | C31: Char | D31: 100 | E31: * | F31: 指定 | G31: 可有 | H31: CMCLAS对应的编码 | I31: SDTM | J31: =ROW()-13 -> 18 | K31: 对应于 CMCLAS 的代码。可能从编码中获得。如编码为一类时则赋值为代码如果使用字典编码为多个类别,则遵循章节4:4.1.2.8.3 或不给CMCLASCD赋值。
A32: CMDOSE | B32: 单次剂量 | C32: Num | F32: CRF Page 60 | G32: 可有 | H32: =HYPERLINK("#CMTRT!B1","Conversion Definition refer to CMTRT sheet") -> Conversion Definition refer to CMTRT sheet | I32: SDTM | J32: =ROW()-13 -> 19 | K32: CMTRT 的用量。当 CMDOSTXT 有值时,不需要赋值。
A33: CMDOSTXT | B33: 单次剂量描述 | C33: Char | D33: 100 | F33: CRF Page 60 | G33: 可有 | H33: =HYPERLINK("#CMTRT!B1","Conversion Definition refer to CMTRT sheet") -> Conversion Definition refer to CMTRT sheet | I33: SDTM | J33: =ROW()-13 -> 20 | K33: 以文本形式采集的给药剂量或剂量范围信息。单位可能存储 在CMDOSU。例如:200-400,15-20。当CMDOSE有值时,不需要赋值。
A34: CMDOSU | B34: 剂量单位 | C34: Char | D34: 20 | E34: (UNIT) | F34: CRF Page 60 | G34: 可有 | H34: [RAW.CM]: 如果CM.CMDOSU='1', 那么CMDOSU='毫克'; 如果CM.CMDOSU='2', 那么CMDOSU='微克'; 如果CM.CMDOSU='3', 那么CMDOSU='克'; 如果CM.CMDOSU='4', 那么CMDOSU='毫升'; 如果CM.CMDOSU='5', 那么CMDOSU='国际单位'; 如果CM.CMDOSU='99', 那么CMDOSU='其他'. | I34: SDTM | J34: =ROW()-13 -> 21 | K34: CMDOSE、CMDOSTXT、及CMDOSTOT的单位,例如:纳克(ng),毫克(mg),毫克/千克(mg/kg)。
A35: CMDOSFRM | B35: 剂型 | C35: Char | D35: 20 | E35: (FRM) | F35: CRF Page 60 | G35: 可有 | H35: [RAW.CM]: 如果CM.CMDOSFRM='01', 那么CMDOSFRM='丸剂'; 如果CM.CMDOSFRM='02', 那么CMDOSFRM='冲剂'; 如果CM.CMDOSFRM='03', 那么CMDOSFRM='片剂'; 如果CM.CMDOSFRM='04', 那么CMDOSFRM='膜剂'; 如果CM.CMDOSFRM='05', 那么CMDOSFRM='栓剂'; 如果CM.CMDOSFRM='06', 那么CMDOSFRM='注射剂/注射用'; 如果CM.CMDOSFRM='07', 那么CMDOSFRM='软膏剂'; 如果CM.CMDOSFRM='08', 那么CMDOSFRM='胶囊剂'; 如果CM.CMDOSFRM='09', 那么CMDOSFRM='气雾剂'; 如果CM.CMDOSFRM='10', 那么CMDOSFRM='滴剂'; 如果CM.CMDOSFRM='11', 那么CMDOSFRM='乳剂'; 如果CM.CMDOSFRM='99', 那么CMDOSFRM='其他. | I35: SDTM | J35: =ROW()-13 -> 22 | K35: CMTRT 的剂型。例如:片剂、洗液。
A36: CMDOSFRQ | B36: 频率 | C36: Char | D36: 20 | E36: (FREQ) | F36: CRF Page 60 | G36: 可有 | H36: [RAW.CM]: 如果CM.CMDOSFRQ='01', 那么CMDOSFRQ='一日一次'; 如果CM.CMDOSFRQ='02', 那么CMDOSFRQ='一日两次'; 如果CM.CMDOSFRQ='03', 那么CMDOSFRQ='一日三次'; 如果CM.CMDOSFRQ='04', 那么CMDOSFRQ='一日四次'; 如果CM.CMDOSFRQ='05', 那么CMDOSFRQ='隔日'; 如果CM.CMDOSFRQ='06', 那么CMDOSFRQ='一周一次'; 如果CM.CMDOSFRQ='07', 那么CMDOSFRQ='两周一次'; 如果CM.CMDOSFRQ='08', 那么CMDOSFRQ='一月一次'; 如果CM.CMDOSFRQ='09', 那么CMDOSFRQ='按需'; 如果CM.CMDOSFRQ='99', 那么CMDOSFRQ='其他. | I36: SDTM | J36: =ROW()-13 -> 23 | K36: 通常表达为每段特定时间给于指定剂量(CMDOSE)药物次数。例如:BID(每日两次),Q12H(每12小时一次)。
A37: CMDOSTOT | B37: 每日总剂量 | C37: Num | G37: 可有 | I37: SDTM | J37: =ROW()-13 -> 24 | K37: 以CMDOSU为单位的CMTRT每日总剂量。在用每日总剂量来记录给药时使用。如果周期不是一天,总剂量可以记录在补充修饰语变量中。
A38: CMDOSRGM | B38: 计划给药方案 | C38: Char | D38: 100 | G38: 可有 | I38: SDTM | J38: =ROW()-13 -> 25 | K38: 适用于干预的预定安排或方案的文本描述。例如:给药两周,停药两周。
A39: CMROUTE | B39: 给药途径 | C39: Char | D39: 20 | E39: (ROUTE) | F39: CRF Page 60 | G39: 可有 | H39: [RAW.CM]: 如果CM.CMROUTE='1', 那么CMROUTE='口服'; 如果CM.CMROUTE='2', 那么CMROUTE='皮下注射'; 如果CM.CMROUTE='3', 那么CMROUTE='经皮给药'; 如果CM.CMROUTE='4', 那么CMROUTE='静脉给药'; 如果CM.CMROUTE='5', 那么CMROUTE='眼内'; 如果CM.CMROUTE='6', 那么CMROUTE='肌肉注射'; 如果CM.CMROUTE='7', 那么CMROUTE='吸入'; 如果CM.CMROUTE='99', 那么CMROUTE='其他'. | I39: SDTM | J39: =ROW()-13 -> 26 | K39: CMTRT的给药途径,例如口服、静脉注射。
A40: CMSTDTC | B40: 开始日期/时间 | C40: Char | D40: 20 | E40: ISO 8601 | F40: CRF Pages 9 60 64 | G40: 可有 | H40: =HYPERLINK("#CMTRT!B1","Conversion Definition refer to CMTRT sheet") -> Conversion Definition refer to CMTRT sheet | I40: SDTM | J40: =ROW()-13 -> 27
A41: CMENDTC | B41: 结束日期/时间 | C41: Char | D41: 20 | E41: ISO 8601 | F41: CRF Pages 9 60 64 | G41: 可有 | H41: =HYPERLINK("#CMTRT!B1","Conversion Definition refer to CMTRT sheet") -> Conversion Definition refer to CMTRT sheet | I41: SDTM | J41: =ROW()-13 -> 28
...

Sheet CMTRT
A1: RAW DATA | B1: CMSPID | C1: CMTRT | D1: CMCAT | E1: CMSCAT | F1: CMINDC | G1: CMDOSE | H1: CMDOSTXT | I1: CMSTDTC | J1: CMENDTC | K1: CMENRF | L1: Conversion Definition
A2: DH, DH_DE | B2: DH.SN | C2: DH_DE.DHNAME | D2: ="既往肿瘤药物治疗史" | E2: DH.DHTERM | F2: DH.DHPUR | I2: ISO 8601(DH.DHSTDAT) | J2: ISO 8601(DH.DHENDAT) | K2: ="持续",如果DH.DHONGO='1' | L2: DH.YN='1'
A3: CM | B3: CM.SN | C3: CM.CMTRT | D3: ="既往及合并用药" | F3: 如果CM.CMREA='1',那么CMINDC='不良事件'; 如果CM.CMREA='2',那么CMINDC='既往/现病史'; 如果CM.CMREA='99',那么CMINDC='其他'; | G3: =CM.CMDSTXT的数值型格式,如果CM.CMDSTXT为数字 | H3: =CM.CMDSTXT如果CM.CMDSTXT不为数字 | I3: ISO 8601(CM.CMSTDAT) | J3: ISO 8601(CM.CMENDAT) | K3: ="持续",如果CM.CMONGO='1' | L3: CM.YN='1'
A4: AD, AD_DE | B4: AD.SN | C4: AD_DE.ADNAME | D4: ="后续肿瘤药物治疗" | E4: AD.ADTERM | I4: ISO 8601(AD.ADSTDAT) | J4: ISO 8601(AD.ADENDAT) | K4: ="持续",如果AD.ADONGO='是' | L4: AD.YN='1'
A6: CM

Sheet CO
A1: CO Domain Mapping Specifications
A2: 方案编号: | D2: =CONTENT!$B$3 -> XXXXX
A3: SDTM 版本: | D3: =CONTENT!$B$4 -> 3.2
A4: SDTM 数据集描述: | D4: =CONTENT!$B$10 -> 备注
A5: SDTM 数据集结构: | D5: =CONTENT!$C$10 -> 每个受试者每条备注一条记录
A6: 程序名称: | D6: =CONTENT!$D$10 -> co.sas
A7: 常规观测分类: | D7: =CONTENT!$E$10 -> 特殊用途
A8: 数据来源: | D8: =CONTENT!$F$10 -> XXXX
A9: 关键变量: | D9: =CONTENT!$G$10 -> STUDYID, USUBJID, COSEQ
A10: 排序变量: | D10: =CONTENT!$H$10 -> STUDYID, USUBJID, COSEQ
A11: 提取规则: | D11: =CONTENT!$I$10 -> XXXX
A13: 变量名称 | B13: 变量标签 | C13: 类型 | D13: 长度 | E13: 受控术语或格式 | F13: 来源 | G13: 核心类别 | H13: 转换定义 | I13: 变量类型 | J13: 变量顺序 | K13: 定义注释
A14: STUDYID | B14: 研究标识符 | C14: Char | D14: 20 | G14: 必需 | I14: SDTM | J14: =ROW()-13 -> 1 | K14: 研究的唯一标识符
A15: DOMAIN | B15: 域名缩写 | C15: Char | D15: 2 | E15: CO | G15: 必需 | I15: SDTM | J15: =ROW()-13 -> 2 | K15: 双字符域名缩写
A16: RDOMAIN | B16: 关联域名缩写 | C16: Char | D16: 2 | E16: * | G16: 可有 | I16: SDTM | J16: =ROW()-13 -> 3 | K16: 父记录两个字符的域名缩写。
A17: USUBJID | B17: 受试者唯一标识符 | C17: Char | D17: 30 | G17: 必需 | I17: SDTM | J17: =ROW()-13 -> 4 | K17: 同一产品的所有申请或递交的研究中受试者的唯一标识符。
A18: COSEQ | B18: 序号 | C18: Num | G18: 必需 | I18: SDTM | J18: =ROW()-13 -> 5 | K18: 给出序列号以确保域内主题记录的唯一性。可以是任何有效数字。
A19: IDVAR | B19: 标识变量 | C19: Char | D19: 25 | E19: * | G19: 可有 | I19: SDTM | J19: =ROW()-13 -> 6 | K19: 在通用观测数据类型数据集中,用于识别关联记录的变量名称。例如:--SEQ, --GRPID。仅在单个注释与某个域记录相关时使用。在单独的CRF上采集的注释为空。
A20: IDVARVAL | B20: 标识变量值 | C20: Char | D20: 200 | G20: 可有 | I20: SDTM | J20: =ROW()-13 -> 7 | K20: IDVAR 中描述标识变量值。如果SEQ用于描述记录,那么--SEQ录入在此。仅在单个注释与域记录相关时使用。在单独的 CRF 上采集的评论为空。
A21: COREF | B21: 备注参照 | C21: Char | D21: 200 | G21: 可有 | I21: SDTM | J21: =ROW()-13 -> 8 | K21: 申办者定义的与注释相关的参考。可以是 CRF 页码(例如 650),或模块名称(例如 DEMOG),或标识参考的信息的组合(例如 650-VITALS-VISIT 2)。
A22: COVAL | B22: 备注 | C22: Char | D22: 200 | G22: 必需 | I22: SDTM | J22: =ROW()-13 -> 9 | K22: 备注文本。超过 200 个字符的文本可以添加到其他列COVAL1-COVALn。见假设 3。
A23: COEVAL | B23: 评估者 | C23: Char | D23: 100 | E23: * | G23: 可有 | I23: SDTM | J23: =ROW()-13 -> 10 | K23: 用于描述注释的发起者。示例:中央,审评员,调查委员会,首席研究者。
A24: CODTC | B24: 采集日期/时间 | C24: Char | D24: 20 | E24: ISO 8601 | G24: 可有 | I24: SDTM | J24: =ROW()-13 -> 11 | K24: 备注页提供备注的采集日期/时间。如果这是另一个域的子记录或未采集备注日期,则应为空。
A26: CONTENT

Sheet DA
A1: DA Domain Mapping Specifications
A2: 方案编号: | D2: =CONTENT!$B$3 -> XXXXX
A3: SDTM 版本: | D3: =CONTENT!$B$4 -> 3.2
A4: SDTM 数据集描述: | D4: =CONTENT!$B$11 -> 药物收发记录
A5: SDTM 数据集结构: | D5: =CONTENT!$C$11 -> 每个受试者每个药物收发情况一条记录
A6: 程序名称: | D6: =CONTENT!$D$11 -> da.sas
A7: 常规观测分类: | D7: =CONTENT!$E$11 -> 发现
A8: 数据来源: | D8: =CONTENT!$F$11 -> XXXX
A9: 关键变量: | D9: =CONTENT!$G$11 -> STUDYID, USUBJID, DATESTCD, DADTC
A10: 排序变量: | D10: =CONTENT!$H$11 -> STUDYID, USUBJID, DATESTCD, DADTC
A11: 提取规则: | D11: =CONTENT!$I$11 -> XXXX
A13: 变量名称 | B13: 变量标签 | C13: 类型 | D13: 长度 | E13: 受控术语或格式 | F13: 来源 | G13: 核心类别 | H13: 转换定义 | I13: 变量类型 | J13: 变量顺序 | K13: 定义注释
A14: STUDYID | B14: 研究标识符 | C14: Char | D14: 20 | G14: 必需 | I14: SDTM | J14: =ROW()-13 -> 1 | K14: 研究的唯一标识符。
A15: DOMAIN | B15: 域名缩写 | C15: Char | D15: 2 | E15: DA | G15: 必需 | I15: SDTM | J15: =ROW()-13 -> 2 | K15: 两字符域名缩写。
A16: USUBJID | B16: 受试者唯一标识符 | C16: Char | D16: 30 | G16: 必需 | I16: SDTM | J16: =ROW()-13 -> 3 | K16: 同一产品的所有申请或递交的研究中受试者的唯一标识符。
A17: DASEQ | B17: 序号 | C17: Num | G17: 必需 | I17: SDTM | J17: =ROW()-13 -> 4 | K17: 序号,确保记录在域中的唯一性。可以是任何有效数字。
A18: DAGRPID | B18: 组合ID | C18: Char | D18: 25 | G18: 可有 | I18: SDTM | J18: =ROW()-13 -> 5 | K18: 用来关联域内同一个受试者的一组相关记录。
A19: DAREFID | B19: 参考ID | C19: Char | D19: 25 | G19: 可有 | I19: SDTM | J19: =ROW()-13 -> 6 | K19: 内部或外部标识符,例如:标签号。
A20: DASPID | B20: 自定义标识符 | C20: Char | D20: 25 | G20: 可有 | I20: SDTM | J20: =ROW()-13 -> 7 | K20: 申办者定义的参考编号。可能作为显示行标识符预先设定在CRF上,或者被定义在申办者操作数据库中。例如:药物收发记录页上的行号,药物标签码。
A21: DATESTCD | B21: 评估项简称 | C21: Char | D21: 8 | E21: * | G21: 必需 | I21: SDTM | J21: =ROW()-13 -> 8 | K21: DATEST的简称,用作数据集从纵向格式转化为横向格式时的列名。缩写值长度不得超过8个字符,不能以数字开头,不得包含除字母、数字或下划线之外的字符。例如:DISPAMT、RETAMT。
A22: DATEST | B22: 评估项名称 | C22: Char | D22: 40 | E22: * | G22: 必需 | I22: SDTM | J22: =ROW()-13 -> 9 | K22: 对应主题变量、药物收发评估测试或测量的字面名称。DATEST中的值不能超过40个字符。例如:分发数量(Dispensed Amount),返还数量(Returned Amount)。
A23: DACAT | B23: 类别 | C23: Char | D23: 100 | E23: * | G23: 可有 | I23: SDTM | J23: =ROW()-13 -> 10 | K23: 用于定义相关记录的分类。例如,研究药物(STUDY MEDICATION)、急救药品(RESCUE MEDICATION)。
A24: DASCAT | B24: 子类 | C24: Char | D24: 100 | E24: * | G24: 可有 | I24: SDTM | J24: =ROW()-13 -> 11 | K24: 用于定义一组相关记录的进一步分类。
A25: DAORRES | B25: 原始结果 | C25: Char | D25: 200 | G25: 期望 | I25: SDTM | J25: =ROW()-13 -> 12 | K25: 原始接收或采集的药物收发评估的结果。
A26: DAORRESU | B26: 原始单位 | C26: Char | D26: 20 | E26: (UNIT) | G26: 可有 | I26: SDTM | J26: =ROW()-13 -> 13 | K26: DAORRES的单位。
A27: DASTRESC | B27: 标准化结果 | C27: Char | D27: 200 | G27: 期望 | I27: SDTM | J27: =ROW()-13 -> 14 | K27: 包含从DAORRES中复制或以标准格式或标准单位衍生得出的所有药物收发记录评估的结果值。DASTRESC应以字符型格式复制。DASTRESC应以字符型格式储存所有结果;如果结果是数值型的,也应以数值格式储存在DASTRESN中。
A28: DASTRESN | B28: 标准化结果(N) | C28: Num | G28: 可有 | I28: SDTM | J28: =ROW()-13 -> 15 | K28: 连续型或数值型的结果或发现的标准化格式;由DASTRESC以数值型格式复制。DASTRESN应储存所有的数值型的检查结果或发现。
A29: DASTRESU | B29: 标准化单位 | C29: Char | D29: 20 | E29: (UNIT) | G29: 可有 | I29: SDTM | J29: =ROW()-13 -> 16 | K29: 用于DASTRESC和DASTRESN的标准化单位。
A30: DASTAT | B30: 未做状态 | C30: Char | D30: 10 | E30: (ND) | G30: 可有 | I30: SDTM | J30: =ROW()-13 -> 17 | K30: 用于指出药物收发评估未完成。值为空值(null)或者未完成(NOT NOTE)。
A31: DAREASND | B31: 未做原因 | C31: Char | D31: 200 | G31: 可有 | I31: SDTM | J31: =ROW()-13 -> 18 | K31: 描述未做的原因。DASTAT值为未完成(NOT NOTE)时使用。
A32: VISITNUM | B32: 访视编号 | C32: Num | G32: 期望 | I32: SDTM | J32: =ROW()-13 -> 19 | K32: 1.临床访视号。 2.访视(VISIT)的数值型版本,用于排序。
A33: VISIT | B33: 访视名称 | C33: Char | D33: 100 | G33: 可有 | I33: SDTM | J33: =ROW()-13 -> 20 | K33: 1.方案定义的临床访视描述 。2.可作为VISITNUM和/或VISITDY的补充。
A34: VISITDY | B34: 计划访视日 | C34: Num | G34: 可有 | I34: SDTM | J34: =ROW()-13 -> 21 | K34: 基于人口学数据中RFTDTC的计划访视研究日。
A35: DADTC | B35: 采集日期/时间 | C35: Char | D35: 20 | E35: ISO 8601 | G35: 期望 | I35: SDTM | J35: =ROW()-13 -> 22
A36: DADY | B36: 采集日 | C36: Num | G36: 可有 | I36: SDTM | J36: =ROW()-13 -> 23 | K36: 1.药物收发评估的研究日,以整天数形式度量。2.计算方法必须基于申办方定义在人口学域中的变量RFSTDTC。
A38: CONTENT

Sheet DD
A1: DD Domain Mapping Specifications
A2: 方案编号: | D2: =CONTENT!$B$3 -> XXXXX
A3: SDTM 版本: | D3: =CONTENT!$B$4 -> 3.2
A4: SDTM 数据集描述: | D4: =CONTENT!$B$12 -> 死亡详情
A5: SDTM 数据集结构: | D5: =CONTENT!$C$12 -> 每个受试者每个发现一条记录
A6: 程序名称: | D6: =CONTENT!$D$12 -> dd.sas
A7: 常规观测分类: | D7: =CONTENT!$E$12 -> 发现
A8: 数据来源: | D8: =CONTENT!$F$12 -> XXXX
A9: 关键变量: | D9: =CONTENT!$G$12 -> STUDYID, USUBJID, DDTESTCD, DDDTC
A10: 排序变量: | D10: =CONTENT!$H$12 -> STUDYID, USUBJID, DDTESTCD, DDDTC
A11: 提取规则: | D11: =CONTENT!$I$12 -> XXXX
A13: 变量名称 | B13: 变量标签 | C13: 类型 | D13: 长度 | E13: 受控术语或格式 | F13: 来源 | G13: 核心类别 | H13: 转换定义 | I13: 变量类型 | J13: 变量顺序 | K13: 定义注释
A14: STUDYID | B14: 研究标识符 | C14: Char | D14: 20 | G14: 必需 | I14: SDTM | J14: =ROW()-13 -> 1 | K14: 研究的唯一标识符。
A15: DOMAIN | B15: 域名缩写 | C15: Char | D15: 2 | E15: DD | G15: 必需 | I15: SDTM | J15: =ROW()-13 -> 2 | K15: 两个字符域名缩写。
A16: USUBJID | B16: 受试者唯一标识符 | C16: Char | D16: 30 | G16: 必需 | I16: SDTM | J16: =ROW()-13 -> 3 | K16: 同一产品的所有申请或递交的研究中受试者的唯一标识符。
A17: DDSEQ | B17: 序号 | C17: Num | G17: 必需 | I17: SDTM | J17: =ROW()-13 -> 4 | K17: 序号,确保记录在域中的唯一性。 可以是任何有效数字。
A18: DDTESTCD | B18: 评估项简称 | C18: Char | D18: 8 | E18: * | G18: 必需 | I18: SDTM | J18: =ROW()-13 -> 5 | K18: 在DDTEST中描述的测量、检测或检查的简称。可以作数据集从纵向格式转化为横向格式时的列名。 DDTESTCD 的值不得超过 8 个字符,不能以数字开头(例如:"1TEST"是无效的)。DDTESTCD不能包含除字母、数字或下划线之外的字符。例如:DIAGPRIM, DIAGSEC, DTHWIT
A19: DDTEST | B19: 评估项名称 | C19: Char | D19: 40 | G19: 必需 | I19: SDTM | J19: =ROW()-13 -> 6 | K19: DDTESTCD 全称。DDTEST 中的值不能超过 40 个字符。例如:主要诊断(Primary Diagnosis)、次要诊断(Secondary Diagnosis)、死亡是否被见证(Was Death Witnessed?)
A20: DDORRES | B20: 原始结果 | C20: Char | D20: 200 | G20: 期望 | I20: SDTM | J20: =ROW()-13 -> 7 | K20: 原始接收或采集的定义在DDTEST中的检测的结果。
A21: DDSTRESC | B21: 标准化结果 | C21: Char | D21: 200 | G21: 期望 | I21: SDTM | J21: =ROW()-13 -> 8 | K21: 包含从DDORRES中复制或以标准格式衍生得出的结果值。
A22: DDRESCAT | B22: 结果类别 | C22: Char | D22: 100 | E22: * | G22: 可有 | I22: SDTM | J22: =ROW()-13 -> 9 | K22: 用于对发现的结果分类。例如:与治疗相关的(TREATMENT RELATED)、与治疗不相关的 (NONTREATMENT RELATED)、不确定的(UNDETERMINED)、偶然的(ACCIDENTAL)
A23: DDEVAL | B23: 评估者 | C23: Char | D23: 100 | E23: (EVAL) | G23: 可有 | I23: SDTM | J23: =ROW()-13 -> 10 | K23: 评估者的角色。
A24: DDDTC | B24: 采集日期/时间 | C24: Char | D24: 20 | E24: ISO 8601 | G24: 期望 | I24: SDTM | J24: =ROW()-13 -> 11 | K24: 诊断或其他死亡评估的采集时间,以ISO 8601 格式显示。不一定是死亡时间。
A25: DDDY | B25: 采集日 | C25: Num | G25: 可有 | I25: SDTM | J25: =ROW()-13 -> 12 | K25: 采集的研究日,以整天数形式度量。计算方法必需基于申办方定义的人口学域(DM)中的变量RFSTDTC。
A27: CONTENT

Sheet DM
A1: DM Domain Mapping Specifications
A2: 方案编号: | D2: =CONTENT!$B$3 -> XXXXX
A3: SDTM 版本: | D3: =CONTENT!$B$4 -> 3.2
A4: SDTM 数据集描述: | D4: =CONTENT!$B$13 -> 人口学
A5: SDTM 数据集结构: | D5: =CONTENT!$C$13 -> 每个受试者一条记录
A6: 程序名称: | D6: =CONTENT!$D$13 -> dm.sas
A7: 常规观测分类: | D7: =CONTENT!$E$13 -> 特殊用途
A8: 数据来源: | D8: =CONTENT!$F$13 -> DM, EX, ICF, SV, RAND, PE, LB, TCT, TC_DE, VS1, VS1_DE, VS1_OTH, VS2, ECG, EG, ECOG, EG_DE, EOT, ADAE_DE, IMT, IM_DE, AE, SF, TUCL, VIR, TLB, NTLB, HT, WT, CCR, HCG, OT, DS, DR, SUBJECT, ADA_DE, NL_DE, NTL_DE, OBT, OB_DE, OEA, PKD_DE, PKND_DE, TL_DE, UNSO_DE
A9: 关键变量: | D9: =CONTENT!$G$13 -> STUDYID, USUBJID
A10: 排序变量: | D10: =CONTENT!$G$13 -> STUDYID, USUBJID
A11: 提取规则: | D11: =CONTENT!$I$13 -> ALL
A13: 变量名称 | B13: 变量标签 | C13: 类型 | D13: 长度 | E13: 受控术语或格式 | F13: 来源 | G13: 核心类别 | H13: 转换定义 | I13: 变量类型 | J13: 变量顺序 | K13: 定义注释
A14: STUDYID | B14: 研究标识符 | C14: Char | D14: 20 | F14: 指定 | G14: 必需 | H14: QL1706-101 | I14: SDTM | J14: =ROW()-13 -> 1 | K14: 研究的唯一标识符
A15: DOMAIN | B15: 域名缩写 | C15: Char | D15: 2 | E15: DM | F15: 指定 | G15: 必需 | H15: DM | I15: SDTM | J15: =ROW()-13 -> 2 | K15: 双字符域名缩写
A16: USUBJID | B16: 受试者唯一标识符 | C16: Char | D16: 30 | F16: 衍生 | G16: 必需 | H16: 通过 "-" 连接 STUDYID, SITEID, SUBJID. (例:QL1706-101-01-01001). | I16: SDTM | J16: =ROW()-13 -> 3 | K16: 同一产品的所有申请或递交的研究中受试者的唯一标识符
A17: SUBJID | B17: 受试者标识符 | C17: Char | D17: 8 | F17: CRF Page 2 | G17: 必需 | H17: =SUBJECT.SUBJID | I17: SDTM | J17: =ROW()-13 -> 4 | K17: 受试者标志,在研究中必需是唯一的,通常为采集在CRF 中的为受试者ID
A18: RFSTDTC | B18: 受试者参照开始日期/时间 | C18: Char | D18: 20 | E18: ISO 8601 | F18: 衍生 | G18: 期望 | H18: 每位受试者第一次给药日期 =ISO 8601(EX.EXDAT, EXSTTIM)中第一个非空日期/时间. | I18: SDTM | J18: =ROW()-13 -> 5 | K18: 受试者参照开始日期/时间,以ISO 8601 格式表示。通常等于受试者第一次暴露于研究治疗的日期/时间。 要求所有随机受试者具有。如果受试者没有符合日期要求的里程碑,如筛选失败或者受试者未分组,则值为空。
A19: RFENDTC | B19: 受试者参照结束日期/时间 | C19: Char | D19: 20 | E19: ISO 8601 | F19: 衍生 | G19: 期望 | H19: 每位受试者最后一次给药日期 =ISO 8601(EX.EXDAT, EX.EXENTIM)中最晚的一条非空时间; 注意: 如果RFSTDTC是空的话,RFENDTC应该为空. | I19: SDTM | J19: =ROW()-13 -> 6 | K19: 受试者参照结束日期/时间,以ISO 8601 格式表示。通常等于受试者结束试验的日期/时间,也常等于受试者最后一次暴露于研究治疗的日期/时间。要求所有随机受试者具有。若受试者筛选失败或者未分组,则值为空。
A20: RFXSTDTC | B20: 首次研究治疗日期/时间 | C20: Char | D20: 20 | E20: ISO 8601 | F20: 衍生 | G20: 期望 | H20: =RFSTDTC | I20: SDTM | J20: =ROW()-13 -> 7 | K20: 任意试验方案指定治疗的首次暴露日期,等同于最早一次EXSTDTC 的变量值
A21: RFXENDTC | B21: 末次研究治疗日期/时间 | C21: Char | D21: 20 | E21: ISO 8601 | F21: 衍生 | G21: 期望 | H21: =RFENDTC | I21: SDTM | J21: =ROW()-13 -> 8 | K21: 任意试验方案指定治疗的末次暴露日期,等同于最迟一次EXENDTC 的变量值(当EXENDTC没有采集或者为空,则等同于最后一次EXSTDTC的值).
A22: RFICDTC | B22: 知情同意日期/时间 | C22: Char | D22: 20 | E22: ISO 8601 | F22: CRF Page 4 | G22: 期望 | H22: =ISO 8601(ICF.ICFDAT) 注:如果一个人有多条,则选择 ICF.ICFVER不为'1.2版'的记录。 | I22: SDTM | J22: =ROW()-13 -> 9 | K22: 知情同意的日期/时间以ISO 8601 字符格式表示。 如果该研究计划书里程碑被记录在案,这将与处置域中的知情同意的日期相同。 仅在不采集知情同意书日期的研究中为空。
A23: RFPENDTC | B23: 参与结束日期/时间 | C23: Char | D23: 20 | E23: ISO 8601 | F23: 衍生 | G23: 期望 | H23: 等于SV.VISDAT, ICF.ICFDAT, TUCL.TUCLDAT, PE.PEDAT, LB.LBDAT, CCR.CCRDAT, VIR.VIRDAT, HBV.HBVDAT, ECG.ECGDAT, TLB_DE.TLBDAT, NTLB_DE.NTLBDAT, ECOG.ECOGDAT, TCT.TCTDAT, TC_DE.TCDAT, VS1.VS1DAT, VS2.VS2DAT, EG.EGDAT, HCG.HCGDAT, RAND.RANDDAT, EX.EXDAT, PKD_DE.PKDDAT, PKE_DE.PKEDAT, PKND_DE.PKNDDAT, PKU.PKUDAT, ADA_DE.ADADAT, ADAE_DE.ADAEDAT, ADAU.ADAUDAT, IM_DE.IMDAT, OT.OTDAT, AE.AESTDAT, AE.SAESTDAT, AE.SEVSTDAT, AE.AEENDAT, CM.CMSTDAT, CM.CMENDAT, PR.PRSTDAT, PR.PRENDAT, EOT.EOTDAT, SF.SFLADAT, AD.ADSTDTC, AD.ADENDTC, AR.ARSTDTC, AR.ARENDTC, ASU.ASUDAT, AO.AOSTDTC, AO.AOENDTC, DS.DSDAT, DR.DRDAT, TL_DE.TLDAT, NTL_DE.NTLDAT, NL_DE.NLDAT, OEA.OEADAT, IMT.IMTDAT, OB_DE.OBDAT, HT.HTDAT, WT.WTDAT, OBT.OBTDAT, UNSO_DE.UNSODAT中最后一条非缺失值中的最大值. | I23: SDTM | J23: =ROW()-13 -> 10 | K23: 计划书定义的受试者结束参与或随访的日期/时间,ISO 8601 字符格式表示。 应对应于最后一个已知的接触日期。 例子包括完成日期,撤退日期,最后的随访日期,记录在案的随访丢失日期或死亡日期.
A24: DTHDTC | B24: 死亡日期/时间 | C24: Char | D24: 20 | E24: ISO 8601 | F24: CRF Pages 59 68 69 | G24: 期望 | H24: 如果 DR.DRDAT^="" 则 DTHDTC=ISO 8601(DR.DRDAT); 如果 AE.AEOUT="5" 则 DTHDTC=ISO 8601(AE.AEENDAT); 如果 DS.DSREA="2" 则 DTHDTC=ISO 8601(DS.DSDAT); | I24: SDTM | J24: =ROW()-13 -> 11 | K24: 任何死亡的受试者的死亡日期/时间,以ISO 8601 格式表示。 应当表示在临床试验数据库采集的日期/时间
A25: DTHFL | B25: 死亡标帜 | C25: Char | D25: 3 | E25: (NY) | F25: 衍生 | G25: 期望 | H25: ="是" 如果DTHDTC不为空, 否则为空. | I25: SDTM | J25: =ROW()-13 -> 12 | K25: 标识受试者死亡。 值为Y 或者为空。 即使死亡日期未知也应当被填充。
A26: SITEID | B26: 研究中心标识符 | C26: Char | D26: 4 | F26: CRF Page 2 | G26: 必需 | H26: =SUBJECT.SITEID | I26: SDTM | J26: =ROW()-13 -> 13 | K26: 研究中心唯一标识符
A27: INVID | B27: 研究者标识符 | C27: Char | D27: 20 | F27: CRF Page 2 | G27: 可有 | H27: =SUBJECT.INVID | I27: SDTM | J27: =ROW()-13 -> 14 | K27: 用于描述某个研究的研究者标识符。 可能进一步用于研究中心编号。 当INVID 和SITEID 相同时无需保留
A28: INVNAM | B28: 研究者姓名 | C28: Char | D28: 100 | F28: CRF Page 2 | G28: 可有 | H28: =SUBJECT.INVNAME | I28: SDTM | J28: =ROW()-13 -> 15 | K28: 某个研究中心研究者姓名
A29: BRTHDTC | B29: 出生日期/时间 | C29: Char | D29: 20 | E29: ISO 8601 | F29: CRF Page 5 | G29: 可有 | H29: =DM.BRTHDAT | I29: SDTM | J29: =ROW()-13 -> 16 | K29: 受试者出生日期/时间
A30: AGE | B30: 年龄 | C30: Num | F30: CRF Page 5 | G30: 期望 | H30: =DM.AGE | I30: SDTM | J30: =ROW()-13 -> 17 | K30: 以年龄单位表达的年龄。 可能衍生于RFSTDTC 和BRTHDTC,不是在所有情况下BRTHDTC 都可用(由于受试者隐私问题)。
A31: AGEU | B31: 年龄单位 | C31: Char | D31: 6 | E31: (AGEU) | F31: CRF Page 5 | G31: 期望 | H31: 当AGE不为空时,AGEU="岁". | I31: SDTM | J31: =ROW()-13 -> 18 | K31: 年龄相关的单位
A32: SEX | B32: 性别 | C32: Char | D32: 6 | E32: (SEX) | F32: CRF Page 5 | G32: 必需 | H32: 当DM.SEX="1"时, SEX="男性"; 当DM.SEX="2"时, SEX="女性". | I32: SDTM | J32: =ROW()-13 -> 19 | K32: 受试者性别
A33: RACE | B33: 种族 | C33: Char | D33: 20 | E33: (RACE) | F33: 指定 | G33: 期望 | H33: 亚裔 | I33: SDTM | J33: =ROW()-13 -> 20 | K33: 受试者种族。 关于采集种族的指南,申办者应参考"种族和种族数据的采集"。 《临床试验》(FDA,2005 年9 月)(HTTP://www.fda.gv/RealTraceIdvices/GuangsEs/UCM12634.0.HTM)参见关于种族的假设。
A34: ETHNIC | B34: 族群 | C34: Char | D34: 25 | E34: (ETHNIC) | F34: CRF Page 5 | G34: 可有 | H34: 当DM.ETHNIC="1"时, ETHNIC="汉族"; 当DM.ETHNIC="99"时, ETHNIC="其他". | I34: SDTM | J34: =ROW()-13 -> 21 | K34: 受试者族群。 关于采集族群的指南,申办者应参考"种族和种族数 据的采集"。 《临床试验》(FDA,2005 年9 月)(HTTP://www.fda.gv/RealTraceIdvices/GuangsEs/UCM12634.0.HTM) 参见关于族群的假设。 (http://www.fda.gov/RegulatoryInformation/Guidances/ucm126340.htm).
A35: ARMCD | B35: 计划分组编码 | C35: Char | D35: 20 | F35: 指定 | G35: 必需 | H35: 如果ARM="筛选失败", ARMCD="SCRNFAIL". 如果ARM="0.3mg/kg", ARMCD="03MG"; 如果ARM="1.0mg/kg", ARMCD="1MG"; 如果ARM="3.0mg/kg", ARMCD="3MG"; 如果ARM="5.0mg/kg", ARMCD="5MG"; 如果ARM="10.0mg/kg", ARMCD="10MG"; 如果ARM="7.5mg/kg", ARMCD="75MG"; 如果ARM="未指定", ARMCD="NOTASSGN". | I35: SDTM | J35: =ROW()-13 -> 22 | K35: ARMCD 在20 个字符以内不受特殊字符限制,ARMCD 的最大长度比其它"短"变量长,以适应交叉试验可能需要的值类型。 例如,如果七周期交叉的ARMCD 值是使用每个处理和分离连字符的双字符缩写来构建的,那么ARMCD 值的长度将是20。
A36: ARM | B36: 计划分组描述 | C36: Char | D36: 100 | F36: CRF Pages 45 47 | G36: 必需 | H36: 当RAND.RANDYN="5"时, ARM="筛选失败"; 当EX.EXTDOS="1"时, ARM="0.3mg/kg"; 当EX.EXTDOS="2"时, ARM="1.0mg/kg"; 当EX.EXTDOS="3"时, ARM="3.0mg/kg"; 当EX.EXTDOS="4"时, ARM="5.0mg/kg"; 当EX.EXTDOS="5"时, ARM="10.0mg/kg"; 当EX.EXTDOS="6"时, ARM="7.5mg/kg"; 当RAND.RANDYN="2",但没有用药记录,ARM="未指定". | I36: SDTM | J36: =ROW()-13 -> 23 | K36: 受试者被分配的所在组别的名称
A37: ACTARMCD | B37: 实际分组编码 | C37: Char | D37: 20 | F37: 指定 | G37: 必需 | H37: 如果ACTARM="筛选失败" 那么ACTARMCD="SCRNFAIL"; 如果ACTARM="未治疗" 那么ACTARMCD="NOTTRT"; 如果RFSTDTC不为空,ACTARMCD=ARMCD. | I37: SDTM | J37: =ROW()-13 -> 24 | K37: 实际组别代码。 当为非计划组别(未存在于试验组别域)时,ACTARMCD 将是"UNPLAN"。 已随机化但未 给药的受试者会被赋予一个"NOTTRT"的值。 筛查失败的受试者应当赋予"SCRNFAIL"的值,未被分配的受试者应被赋值为"NOTASSGN"。 其他情况以试验组别值为准。 ACTARMCD 限于20 个字符,没有特殊的字符限制。 ACTARMCD 的最大长度比其他短变量要长,以适应交叉试验可能需要的值。
A38: ACTARM | B38: 实际分组描述 | C38: Char | D38: 100 | F38: 指定 | G38: 必需 | H38: 如果ARM="筛选失败" , 那么ACTARM="筛选失败" ; 如果RAND.RANDYN="2" 并且该受试者(EX中所有记录EX.EXYN="2"或EX中没有该受试者的记录), ACTARM="未治疗"; 如果RFSTDTC不为空,ACTARM=ARM. | I38: SDTM | J38: =ROW()-13 -> 25 | K38: 实际组别描述。 当为非计划组别(未存在于试验组别域)时,ACTARM 将是"Unplanned Treatment"。 已随机化但未 给药的受试者会被赋予一个"Not Treated"的值。 筛查失败的受试者应当赋予"Screen Failure"的值,未被分配的受试者应被赋值为"Not Assigned"。 其他情况以试验组别值为准。
A39: COUNTRY | B39: 国家 | C39: Char | D39: 6 | E39: (COUNTRY) | F39: 指定 | G39: 必需 | H39: 中国 | I39: SDTM | J39: =ROW()-13 -> 26 | K39: 受试者参与试验的研究中心所在的国家
A40: DMDTC | B40: 采集日期/时间 | C40: Char | D40: 20 | E40: ISO 8601 | F40: CRF | G40: 可有 | I40: SDTM | J40: =ROW()-13 -> 27 | K40: 人口学数据采集日期/时间
A41: DMDY | B41: 采集日 | C41: Num | F41: CRF | G41: 可有 | I41: SDTM | J41: =ROW()-13 -> 28 | K41: 采集数据的研究日,以整数天为单位度量
...

Sheet DS
A1: DS Domain Mapping Specifications
A2: 方案编号: | D2: =CONTENT!$B$3 -> XXXXX
A3: SDTM 版本: | D3: =CONTENT!$B$4 -> 3.2
A4: SDTM 数据集描述: | D4: =CONTENT!$B$14 -> 受试者分布
A5: SDTM 数据集结构: | D5: =CONTENT!$C$14 -> 每个受试者每个完成状态或每个方案里程碑事件一条记录
A6: 程序名称: | D6: =CONTENT!$D$14 -> ds.sas
A7: 常规观测分类: | D7: =CONTENT!$E$14 -> 事件
A8: 数据来源: | D8: =CONTENT!$F$14 -> ICF, RAND, EOT, DS, SDTM.DM, SDTM.SE
A9: 关键变量: | D9: =CONTENT!$G$14 -> STUDYID, USUBJID, DSSTDTC, DSDECOD
A10: 排序变量: | D10: =CONTENT!$H$14 -> STUDYID, USUBJID, DSSTDTC, DSDECOD
A11: 提取规则: | D11: =CONTENT!$I$14 -> ALL
A13: 变量名称 | B13: 变量标签 | C13: 类型 | D13: 长度 | E13: 受控术语或格式 | F13: 来源 | G13: 核心类别 | H13: 转换定义 | I13: 变量类型 | J13: 变量顺序 | K13: 定义注释
A14: STUDYID | B14: 研究标识符 | C14: Char | D14: 20 | F14: 指定 | G14: 必需 | H14: QL1706-101 | I14: SDTM | J14: =ROW()-13 -> 1 | K14: 研究的唯一标识符
A15: DOMAIN | B15: 域名缩写 | C15: Char | D15: 2 | E15: DS | F15: 指定 | G15: 必需 | H15: DS | I15: SDTM | J15: =ROW()-13 -> 2 | K15: 两字符域名缩写
A16: USUBJID | B16: 受试者唯一标识符 | C16: Char | D16: 30 | F16: 衍生 | G16: 必需 | H16: 通过 "-" 连接 STUDYID, SITEID, SUBJID. (例:QL1706-101-01-01001). | I16: SDTM | J16: =ROW()-13 -> 3 | K16: 同一产品的所有申请或递交的研究中受试者的唯一标识符
A17: DSSEQ | B17: 序号 | C17: Num | F17: 衍生 | G17: 必需 | H17: 按照变量STUDYID, USUBJID, DSDECOD, DSSTDTC排序. 在每个USUBJID开始的时候用1开始重新编号 (循环地排序).") | I17: SDTM | J17: =ROW()-13 -> 4 | K17: 序号,确保数据集内一个受试者的唯一性,可以是任何有效数字
A18: DSGRPID | B18: 组合ID | C18: Char | D18: 25 | G18: 可有 | I18: SDTM | J18: =ROW()-13 -> 5 | K18: 用来关联域内同一个受试者的一组相关记录
A19: DSREFID | B19: 参考ID | C19: Char | D19: 25 | G19: 可有 | I19: SDTM | J19: =ROW()-13 -> 6 | K19: 内部或外部标识
A20: DSSPID | B20: 自定义标识符 | C20: Char | D20: 25 | F20: CRF Page 4 | G20: 可有 | H20: =HYPERLINK("#DSTERM!A1","转换定义参考DSTERM表") -> 转换定义参考DSTERM表 | I20: SDTM | J20: =ROW()-13 -> 7 | K20: 申办者定义参考代码,可能预印在CRF上作为明确的行号或在申办者的操作数据库中定义。例如:在"处置"页面上的行号。
A21: DSTERM | B21: 受试者分布事件报告名称 | C21: Char | D21: 200 | F21: CRF Pages 4 45 62 68 | G21: 必需 | H21: =HYPERLINK("#DSTERM!A1","转换定义参考DSTERM表") -> 转换定义参考DSTERM表 | I21: SDTM | J21: =ROW()-13 -> 8 | K21: 事件或试验方案里程碑的名称。DSTERM中的一些术语会与DSDECOD匹配,但是其它的术语(例如,受试者搬家)需要映射到DSDECOD中的受控术语,例如:"失访"。
A22: DSDECOD | B22: 标准化名称 | C22: Char | D22: 200 | E22: (NCOMPLT) | F22: CRF Pages 45 62 68 | G22: 必需 | H22: =HYPERLINK("#DSTERM!A1","转换定义参考DSTERM表") -> 转换定义参考DSTERM表 | I22: SDTM | J22: =ROW()-13 -> 9 | K22: 处置事件或实验方案里程碑的受控术语。实验方案里程碑的示例如:获得知情同意书、随机。
A23: DSCAT | B23: 类别 | C23: Char | D23: 100 | E23: (DSCAT) | F23: CRF Pages 4 45 62 68 | G23: 期望 | H23: =HYPERLINK("#DSTERM!A1","转换定义参考DSTERM表") -> 转换定义参考DSTERM表 | I23: SDTM | J23: =ROW()-13 -> 10 | K23: 用来定义相关记录的分类。DSCAT 现为"预期"变量,而在SDTMIG3.1.1和更早版本中为"许可"变量。从"许可"更改到"预期"是基于区分方案里程碑和/或其它处置事件的需要。如果只有处理事件,DSCAT可以为空;但推荐永远给DSCAT 赋值。
A24: DSSCAT | B24: 子类 | C24: Char | D24: 100 | E24: * | F24: CRF Pages 45 62 68 | G24: 可有 | H24: =HYPERLINK("#DSTERM!A1","转换定义参考DSTERM表") -> 转换定义参考DSTERM表 | I24: SDTM | J24: =ROW()-13 -> 11 | K24: 处置事件的进一步分类
A25: EPOCH | B25: 时期 | C25: Char | D25: 100 | E25: (EPOCH) | F25: 指定 | G25: 可有 | H25: 比较 DSSTDTC和 SE.SESTDTC & SE.SEENDTC 每个人每个时期: 1. EPOCH="筛选期" ,如果 SE.SESTDTC<=DSSTDTC<SE.SEENDTC 且当 SE.EPOCH="筛选期" ( 如果没有 EPOCH 在筛选期之后且当 SE.SESTDTC<=DSSTDTC<=SE.SEENDTC, 则EPOCH="筛选期"); 2. EPOCH="治疗期",如果 SE.SESTDTC<=DSSTDTC<=SE.SEENDTC 且当 SE.EPOCH="治疗期"; 3. EPOCH="随访期",如果 SE.SESTDTC<DSSTDTC<=SE.SEENDTC 且当 SE.EPOCH="随访期"; 4.其他,则将 EPOCH 置空. | I25: SDTM | J25: =ROW()-13 -> 12 | K25: 在DSCAT='"处置事件"'时,可能用到EPOCH。例如:筛选、治疗阶段、随访。
A26: DCDTC | B26: 采集日期/时间 | C26: Char | D26: 20 | E26: ISO 8601 | G26: 可有 | I26: SDTM | J26: =ROW()-13 -> 13
A27: DSSTDTC | B27: 开始日期/时间 | C27: Char | D27: 20 | E27: ISO 8601 | F27: CRF Pages 4 45 62 68 | G27: 期望 | H27: =HYPERLINK("#DSTERM!A1","转换定义参考DSTERM表") -> 转换定义参考DSTERM表 | I27: SDTM | J27: =ROW()-13 -> 14
A28: DSSTDY | B28: 开始日 | C28: Num | F28: 衍生 | G28: 可有 | H28: 计算DSSTDY = (数值型 DSSTDTC - 数值型DM.RFSTDTC). Note: 加 1 如果计算结果大于等于0. | I28: SDTM | J28: =ROW()-13 -> 15 | K28: 与申办者定义的RFSTDTC相关的处置事件开始的研究日。
A29: VERSION | B29: 方案版本号 | C29: Char | D29: 200 | F29: CRF Page 4 | H29: =HYPERLINK("#DSTERM!A1","转换定义参考DSTERM表") -> 转换定义参考DSTERM表 | I29: SUPP | J29: =ROW()-13 -> 16
A30: RANDNO | B30: 入组编号 | C30: Char | D30: 200 | F30: CRF Pages 45 | H30: =HYPERLINK("#DSTERM!A1","转换定义参考DSTERM表") -> 转换定义参考DSTERM表 | I30: SUPP | J30: =ROW()-13 -> 17
A32: CONTENT

Sheet DSTERM
A1: 原始数据集 | B1: 转换定义 | D1: DSSPID | E1: DSCAT | F1: DSSCAT | G1: DSTERM | H1: DSDECOD | I1: DSSTDTC | J1: VERSION | K1: RANDNO
A2: ICF | B2: 如果 ICF.ICFDAT 不为空 | D2: ="01" | E2: ='方案里程碑' | G2: ='知情同意签署' | H2: =' 签署知情同意书' | I2: =ISO 8601(ICF.ICFDAT) | J2: =ICF.ICFVER
A3: RAND | B3: 如果RAND.RANDYN="2" | D3: ="02" | E3: ='处置事件' | F3: ="入组信息" | G3: ="入组成功" | H3: ="入组成功" | I3: =ISO 8601(RAND.RANDDAT) | K3: =RAND.RANDNO
B4: 如果RAND.RANDYN="5" | D4: ="03" | E4: ='处置事件' | F4: ="入组信息" | G4: 如果RAND.RANDREA="1"则DSTERM="不符合入选标准/符合排除标准"; 如果RAND.RANDREA="2"则DSTERM="撤回知情同意书"; 如果RAND.RANDREA="3"则DSTERM="不良事件"; 如果RAND.RANDREA="4"则DSTERM="死亡"; 如果RAND.RANDREA="99"则DSTERM=用":"连接"其他"和RAND.RANDOTH; | H4: 如果RAND.RANDREA="1"则DSDECOD="不符合入选标准/符合排除标准"; 如果RAND.RANDREA="2"则DSDECOD="撤回知情同意书"; 如果RAND.RANDREA="3"则DSDECOD="不良事件"; 如果RAND.RANDREA="4"则DSDECOD="死亡"; 如果RAND.RANDREA="99"则DSDECOD="其他";
A5: EOT | B5: 如果EOT.EOTYN="1" | D5: ="04" | E5: ='处置事件' | F5: ="治疗结束" | G5: 如果EOT.EOTREA="1"则DSTERM="受试者自行退出研究治疗"; 如果EOT.EOTREA="2"则DSTERM=用":"连接"不良事件"和EOT,EOTAENO; 如果EOT.EOTREA="3"则DSTERM="疾病进展,研究者认为有必要停止 研究治疗"; 如果EOT.EOTREA="4"则DSTERM=用":"连接"严重违背方案,且研究者和/或申办方认为有必要停止研究治疗"和EOT.EOTAGA; 如果EOT.EOTREA="5"则DSTERM="女性受试者在研究治疗期间发生妊娠"; 如果EOT.EOTREA="6"则DSTERM="研究终止"; 如果EOT.EOTREA="7"则DSTERM="完成治疗(为期最长2年)"; 如果EOT.EOTREA="99"则DSTERM=用":"连接"其他"和EOT.EOTOTH; | H5: 如果EOT.EOTREA="1"则DSDECOD="受试者自行退出研究治疗"; 如果EOT.EOTREA="2"则DSDECOD="不良事件"; 如果EOT.EOTREA="3"则DSDECOD="疾病进展,研究者认为有必要停止 研究治疗"; 如果EOT.EOTREA="4"则DSDECOD="严重违背方案,且研究者和/或申办方认为有必要停止研究治疗"; 如果EOT.EOTREA="5"则DSDECOD="女性受试者在研究治疗期间发生妊娠"; 如果EOT.EOTREA="6"则DSDECOD="研究终止"; 如果EOT.EOTREA="7"则DSDECOD="完成治疗(为期最长2年)"; 如果EOT.EOTREA="99"则DSDECOD="其他"; | I5: =ISO 8601(EOT.EOTDAT)
A6: DS | D6: ="05" | E6: ='处置事件' | F6: ="研究结束" | G6: 如果DS.DSREA="1"则DSTERM="不良事件"||DS.DSAENO; 如果DS.DSREA="2"则DSTERM="死亡"; 如果DS.DSREA="3"则DSTERM="受试者自行退出"; 如果DS.DSREA="4"则DSTERM="失访"; 如果DS.DSREA="5"则DSTERM="研究结束"; 如果DS.DSREA="6"则DSTERM="申办方终止"; 如果DS.DSREA="99"则DSTERM=用":"连接"其他"和DS.DSREOTH; | H6: 如果DS.DSREA="1"则DSDECOD="不良事件"; 如果DS.DSREA="2"则DSDECOD="死亡"; 如果DS.DSREA="3"则DSDECOD="受试者自行退出"; 如果DS.DSREA="4"则DSDECOD="失访"; 如果DS.DSREA="5"则DSDECOD="研究结束"; 如果DS.DSREA="6"则DSDECOD="申办方终止"; 如果DS.DSREA="99"则DSDECOD="其他"; | I6: =ISO 8601(DS.DSDAT)
A8: =HYPERLINK("#DS!A1","DS") -> DS

Sheet DV
A1: DV Domain Mapping Specifications
A2: 方案编号: | D2: =CONTENT!$B$3 -> XXXXX
A3: SDTM 版本: | D3: =CONTENT!$B$4 -> 3.2
A4: SDTM 数据集描述: | D4: =CONTENT!$B$15 -> 方案偏离
A5: SDTM 数据集结构: | D5: =CONTENT!$C$15 -> 每个受试者每例次方案偏离一条记录
A6: 程序名称: | D6: =CONTENT!$D$15 -> dv.sas
A7: 常规观测分类: | D7: =CONTENT!$E$15 -> 事件
A8: 数据来源: | D8: =CONTENT!$F$15 -> XXXX
A9: 关键变量: | D9: =CONTENT!$G$15 -> STUDYID, USUBJID, DVTERM, DVSTDTC
A10: 排序变量: | D10: =CONTENT!$H$15 -> STUDYID, USUBJID, DVTERM, DVSTDTC
A11: 提取规则: | D11: =CONTENT!$I$15 -> XXXX
A13: 变量名称 | B13: 变量标签 | C13: 类型 | D13: 长度 | E13: 受控术语或格式 | F13: 来源 | G13: 核心类别 | H13: 转换定义 | I13: 变量类型 | J13: 变量顺序 | K13: 定义注释
A14: STUDYID | B14: 研究标识符 | C14: Char | D14: 20 | G14: 必需 | I14: SDTM | J14: =ROW()-13 -> 1 | K14: 研究的唯一标识符
A15: DOMAIN | B15: 域名缩写 | C15: Char | D15: 2 | E15: DV | G15: 必需 | I15: SDTM | J15: =ROW()-13 -> 2 | K15: 两字符域名缩写
A16: USUBJID | B16: 受试者唯一标识符 | C16: Char | D16: 30 | G16: 必需 | I16: SDTM | J16: =ROW()-13 -> 3 | K16: 同一产品的所有申请或递交的研究中受试者的唯一标识符
A17: DVSEQ | B17: 序号 | C17: Num | G17: 必需 | I17: SDTM | J17: =ROW()-13 -> 4 | K17: 序号,确保一个受试者在数据集里唯一性,可以是任何有效数字
A18: DVREFID | B18: 参考ID | C18: Char | D18: 25 | G18: 可有 | I18: SDTM | J18: =ROW()-13 -> 5 | K18: 内部或外部标识符
A19: DVSPID | B19: 自定义标识符 | C19: Char | D19: 25 | G19: 可有 | I19: SDTM | J19: =ROW()-13 -> 6 | K19: 可选的申办者定义参考代码,可能被预先打印在CRF上作为明确的行号或被定义在申办者的操作数据库中。例如:在"处置"页面上的行号。
A20: DVTERM | B20: 方案偏离报告名称 | C20: Char | D20: 200 | G20: 必需 | I20: SDTM | J20: =ROW()-13 -> 7 | K20: 方案偏离标准的本名。例如IVRS流程偏差-没有收到剂量的电话记录。DVTERM值映射DVDECOD中的受控术语,例如治疗偏差。
A21: DVDECOD | B21: 标准化名称 | C21: Char | D21: 200 | E21: * | G21: 可有 | I21: SDTM | J21: =ROW()-13 -> 8 | K21: 方案偏离名称的受控术语。例如:受试者未按方案退出,不满足选择标准,治疗偏差等。
A22: DVCAT | B22: 类别 | C22: Char | D22: 100 | E22: * | G22: 可有 | I22: SDTM | J22: =ROW()-13 -> 9 | K22: 方案偏离标准的分类
A23: DVSCAT | B23: 子类 | C23: Char | D23: 100 | E23: * | G23: 可有 | I23: SDTM | J23: =ROW()-13 -> 10 | K23: 方案偏离的进一步分类
A24: EPOCH | B24: 时期 | C24: Char | D24: 100 | E24: (EPOCH) | G24: 可有 | I24: SDTM | J24: =ROW()-13 -> 11 | K24: 与偏离开始日期/时间相关的时期。例如:治疗阶段、筛选、随访。
A25: DVSTDTC | B25: 开始日期/时间 | C25: Char | D25: 20 | E25: ISO 8601 | G25: 可有 | I25: SDTM | J25: =ROW()-13 -> 12 | K25: 用ISO 8601字符格式表示的偏离开始日期/时间
A26: DVENDTC | B26: 结束日期/时间 | C26: Char | D26: 20 | E26: ISO 8601 | G26: 可有 | I26: SDTM | J26: =ROW()-13 -> 13 | K26: 用ISO 8601字符格式表示的偏离结束的日期/时间
A28: CONTENT

Sheet EC
A1: EC Domain Mapping Specifications
A2: 方案编号: | D2: =CONTENT!$B$3 -> XXXXX
A3: SDTM 版本: | D3: =CONTENT!$B$4 -> 3.2
A4: SDTM 数据集描述: | D4: =CONTENT!$B$16 -> 暴露采集
A5: SDTM 数据集结构: | D5: =CONTENT!$C$16 -> 每个受试者每个方案规定的研究用药每个采集的用法每个情景模式一条记录
A6: 程序名称: | D6: =CONTENT!$D$16 -> ec.sas
A7: 常规观测分类: | D7: =CONTENT!$E$16 -> 干预
A8: 数据来源: | D8: =CONTENT!$F$16 -> EX, SDTM.DM
A9: 关键变量: | D9: =CONTENT!$G$16 -> STUDYID, USUBJID, ECTRT, ECSTDTC, ECENDTC
A10: 排序变量: | D10: =CONTENT!$H$16 -> STUDYID, USUBJID, ECTRT, ECSTDTC, ECENDTC
A11: 提取规则: | D11: =CONTENT!$I$16 -> ALL
A13: 变量名称 | B13: 变量标签 | C13: 类型 | D13: 长度 | E13: 受控术语或格式 | F13: 来源 | G13: 核心类别 | H13: 转换定义 | I13: 变量类型 | J13: 变量顺序 | K13: 定义注释
A14: STUDYID | B14: 研究标识符 | C14: Char | D14: 20 | G14: 必需 | I14: SDTM | J14: =ROW()-13 -> 1 | K14: 研究的唯一标识符
A15: DOMAIN | B15: 域名缩写 | C15: Char | D15: 2 | E15: EC | G15: 必需 | I15: SDTM | J15: =ROW()-13 -> 2 | K15: 两字符域名缩写
A16: USUBJID | B16: 受试者唯一标识符 | C16: Char | D16: 30 | G16: 必需 | I16: SDTM | J16: =ROW()-13 -> 3 | K16: 同一产品的所有申请或递交的研究中受试者的唯一标识符
A17: ECSEQ | B17: 序号 | C17: Num | G17: 必需 | I17: SDTM | J17: =ROW()-13 -> 4 | K17: 序号,确保数据集内一个受试者(或参数,例如试验概要域)的记录的唯一性。可以是任何有效数字。
A18: ECGRPID | B18: 组合ID | C18: Char | D18: 25 | G18: 可有 | I18: SDTM | J18: =ROW()-13 -> 5 | K18: 用来关联域内同一个受试者的一组相关记录。
A19: ECREFID | B19: 参考ID | C19: Char | D19: 25 | G19: 可有 | I19: SDTM | J19: =ROW()-13 -> 6 | K19: 内部或者外部标识(例如,试剂盒编号,瓶标签,药瓶标识)。
A20: ECSPID | B20: 自定义标识符 | C20: Char | D20: 25 | G20: 可有 | I20: SDTM | J20: =ROW()-13 -> 7 | K20: 申办方定义的标识符。可能被预先打印在CRF上作为一个明确的标识符,或者被定义在申办方的操作数据集中。例如:在病例报告表页面上的行标识符。
A21: ECLNKID | B21: 链接ID | C21: Char | D21: 25 | G21: 可有 | I21: SDTM | J21: =ROW()-13 -> 8 | K21: 关联域之间相关记录的标识符。
A22: ECLNKGRP | B22: 链接组合ID | C22: Char | D22: 25 | G22: 可有 | I22: SDTM | J22: =ROW()-13 -> 9 | K22: 关联域之间一组记录的标识符。
A23: ECTRT | B23: 治疗名称 | C23: Char | D23: 200 | E23: * | G23: 必需 | I23: SDTM | J23: =ROW()-13 -> 10 | K23: 在给药期间,方案定义的用于观察的研究治疗名称。
A24: ECMOOD | B24: 情景模式 | C24: Char | D24: 20 | E24: * | G24: 可有 | I24: SDTM | J24: =ROW()-13 -> 11 | K24: 记录中定义干预(活动)是否将要发生或者已经发生的模式或条件。值要与BRIDGE柱(例如,预计的情况,已执行的情况)以及卫生信息交换标准(HL7)中的活动情况(例如,目的,事件)相匹配。例如:预计,已执行。CDISC受控术语要求提交MOOD代码列表中的预计和已执行。
A25: ECCAT | B25: 类别 | C25: Char | D25: 100 | E25: * | G25: 可有 | I25: SDTM | J25: =ROW()-13 -> 12 | K25: 用于定义治疗名称的类别。
A26: ECSCAT | B26: 子类 | C26: Char | D26: 100 | E26: * | G26: 可有 | I26: SDTM | J26: =ROW()-13 -> 13 | K26: 对治疗类别的进一步分类。
A27: ECPRESP | B27: 预设 | C27: Char | D27: 10 | E27: (NY) | G27: 可有 | I27: SDTM | J27: =ROW()-13 -> 14 | K27: 用于预先定义的特定的干预。值应该为"是"或者空。
A28: ECOCCUR | B28: 是否发生 | C28: Char | D28: 10 | E28: (NY) | G28: 可有 | I28: SDTM | J28: =ROW()-13 -> 15 | K28: 当请求采集发生信息时,用于表明一个治疗是否发生。当一个治疗未进行,未服用或者错过的时候,ECOCCUR="否"。
A29: ECDOSE | B29: 单次剂量 | C29: Num | G29: 期望 | I29: SDTM | J29: =ROW()-13 -> 16 | K29: ECTRT数值型给药量。当ECDOSTXT有值时,不需要赋值。
A30: ECDOSTXT | B30: 单次剂量描述 | C30: Char | D30: 100 | G30: 可有 | I30: SDTM | J30: =ROW()-13 -> 17 | K30: 非数值型ECTRT用量。给药量或以文本形式采集的剂量范围的信息。例如:200-400。当ECDOSE有值时,不需要赋值。
A31: ECDOSU | B31: 剂量单位 | C31: Char | D31: 20 | E31: (UNIT) | G31: 期望 | I31: SDTM | J31: =ROW()-13 -> 18 | K31: ECDOSE,ECDOSTOT或ECDOSTXT的单位。
A32: ECDOSFRM | B32: 剂型 | C32: Char | D32: 20 | E32: (FRM) | G32: 期望 | I32: SDTM | J32: =ROW()-13 -> 19 | K32: EXTRT的剂型。例如:片剂,洗液。
A33: ECDOSFRQ | B33: 频率 | C33: Char | D33: 20 | E33: (FREQ) | G33: 可有 | I33: SDTM | J33: =ROW()-13 -> 20 | K33: 通常表示为特定间隔期间重复给药的次数。例如:每2小时一次(Q2H),每日一次(QD),每天两次(BID)。
A34: ECDOSTOT | B34: 每日总剂量 | C34: Num | G34: 可有 | I34: SDTM | J34: =ROW()-13 -> 21 | K34: 以ECDOSU为单位的ECTRT每日总剂量。在用每日总剂量来记录给药时使用。
A35: ECDOSRGM | B35: 计划给药方案 | C35: Char | D35: 100 | G35: 可有 | I35: SDTM | J35: =ROW()-13 -> 22 | K35: 适用于干预的预定安排或方案的文本描述。例如:给药两周,停药两周。
A36: ECROUTE | B36: 给药途径 | C36: Char | D36: 20 | E36: (ROUTE) | G36: 可有 | I36: SDTM | J36: =ROW()-13 -> 23 | K36: 给药途径。例如:口服,静脉注射。
A37: ECLOT | B37: 批号 | C37: Char | D37: 50 | G37: 可有 | I37: SDTM | J37: =ROW()-13 -> 24 | K37: ECTRT批号。
A38: ECLOC | B38: 给药部位 | C38: Char | D38: 40 | E38: (LOC) | G38: 可有 | I38: SDTM | J38: =ROW()-13 -> 25 | K38: 说明给药部位。例如:手臂,嘴唇。
A39: ECLAT | B39: 偏侧 | C39: Char | D39: 40 | E39: (LAT) | G39: 可有 | I39: SDTM | J39: =ROW()-13 -> 26 | K39: 在解剖学位置上进一步修饰给药部位的偏侧。例如:左,右。
A40: ECDIR | B40: 方位 | C40: Char | D40: 40 | E40: (DIR) | G40: 可有 | I40: SDTM | J40: =ROW()-13 -> 27 | K40: 在解剖学位置上进一步修饰给药的方向,例如:前,下,近,上。
A41: ECPORTOT | B41: 部分 | C41: Char | D41: 40 | E41: (PORTOT) | G41: 可有 | I41: SDTM | J41: =ROW()-13 -> 28 | K41: 在解剖学位置上进一步修饰分配,安排的分布。例如:全部的,单独的,分段的。
...

Sheet EG
A1: EG Domain Mapping Specifications
A2: 方案编号: | D2: =CONTENT!$B$3 -> XXXXX
A3: SDTM 版本: | D3: =CONTENT!$B$4 -> 3.2
A4: SDTM 数据集描述: | D4: =CONTENT!$B$17 -> 心电图
A5: SDTM 数据集结构: | D5: =CONTENT!$C$17 -> 每个受试者每个访视每个时间点每次心电图每个发现一条记录
A6: 程序名称: | D6: =CONTENT!$D$17 -> eg.sas
A7: 常规观测分类: | D7: =CONTENT!$E$17 -> 发现
A8: 数据来源: | D8: =CONTENT!$F$17 -> EG, EG_DE, SDTM.DM, SDTM.SE
A9: 关键变量: | D9: =CONTENT!$G$17 -> STUDYID, USUBJID, EGTESTCD, VISITNUM, EGDTC, EGSPID
A10: 排序变量: | D10: =CONTENT!$H$17 -> STUDYID, USUBJID, EGTESTCD, VISITNUM, EGDTC, EGSPID
A11: 提取规则: | D11: =CONTENT!$I$17 -> ALL
A13: 变量名称 | B13: 变量标签 | C13: 类型 | D13: 长度 | E13: 受控术语或格式 | F13: 来源 | G13: 核心类别 | H13: 转换定义 | I13: 变量类型 | J13: 变量顺序 | K13: 定义注释
A14: STUDYID | B14: 研究标识符 | C14: Char | D14: 20 | F14: 指定 | G14: 必需 | H14: QL1706-101 | I14: SDTM | J14: =ROW()-13 -> 1 | K14: 研究的唯一标识符
A15: DOMAIN | B15: 域名缩写 | C15: Char | D15: 2 | E15: EG | F15: 指定 | G15: 必需 | H15: EG | I15: SDTM | J15: =ROW()-13 -> 2 | K15: 两字符域名缩写
A16: USUBJID | B16: 受试者唯一标识符 | C16: Char | D16: 30 | F16: 衍生 | G16: 必需 | H16: 通过 "-" 连接 STUDYID, SITEID, SUBJID. (例:QL1706-101-01-01001). | I16: SDTM | J16: =ROW()-13 -> 3 | K16: 同一产品的所有申请或递交的研究中受试者的唯一标识符。
