Workbook
Name FATESTCD: CODELIST!#REF!
Name OLE_LINK73: CONTENT!$B$3
Name VSTEST: CODELIST!#REF!
Name VSTESTCD: CODELIST!$I$219
Name VSTPT: CODELIST!$I$231
Name VSTPTNUM: CODELIST!$I$239

Sheet CONTENT
A1: SDTM Domain Mapping Specifications
A3: 方案编号 | B3: XXXXX
A4: SDTM 版本 | B4: 3.4
A6: SDTM Domain | B6: SDTM Dataset Description | C6: SDTM Dataset Structure | D6: Program Name | E6: Class | F6: Data Source | G6: Key Variable | H6: Order Variable | I6: Extraction Rule | J6: Documentation | K6: RunOrder
A7: AE | B7: Adverse Events | C7: One record per adverse event per subject | D7: ae.sas | E7: Events | G7: STUDYID, USUBJID, AEDECOD, AESTDTC | H7: STUDYID, USUBJID, AEDECOD, AESTDTC
A8: AG | B8: Procedure Agents | C8: One record per recorded intervention occurrence per subject | D8: ag.sas | E8: Interventions | G8: STUDYID, USUBJID,AGGRPID, AGSPID, AGTRT | H8: STUDYID, USUBJID,AGGRPID, AGSPID, AGTRT
A9: BE | B9: Biospecimen Events | C9: One record per instance per biospecimen event per biospecimen identifier per subject | D9: be.sas | E9: Events | G9: STUDYID, USUBJID, BEREFID, BETERM, BESDTC | H9: STUDYID, USUBJID, BEREFID, BETERM, BESDTC
A10: BS | B10: Biospecimen Findings | C10: One record per measurement per biospecimen identifier per subject | D10: bs.sas | E10: Findings | G10: STUDYID, USUBJID, BSREFID, BSTESTCD | H10: STUDYID, USUBJID, BSREFID, BSTESTCD
A11: CE | B11: Clinical Events | C11: One record per event per subject | D11: ce.sas | E11: Events | G11: STUDYID, USUBJID, CETERM, CESTDTC | H11: STUDYID, USUBJID, CETERM, CESTDTC
A12: CM | B12: Concomitant/Prior Medications | C12: One record per recorded intervention occurrence or constant-dosing interval per subject | D12: cm.sas | E12: Interventions | G12: STUDYID, USUBJID, CMTRT, CMSTDTC | H12: STUDYID, USUBJID, CMTRT, CMSTDTC
A13: CO | B13: Comments | C13: One record per comment per subject | D13: co.sas | E13: Special Purpose | G13: STUDYID, USUBJID, IDVAR, COREF, CODTC | H13: STUDYID, USUBJID, IDVAR, COREF, CODTC
A14: CP | B14: Cell Phenotype Findings | C14: One record per test per specimen per timepoint per visit per subject | D14: cp.sas | E14: Findings | G14: STUDYID, USUBJID, CPTESTCD, CPSPEC, VISITNUM, CPTPTREF, CPTPTNUM | H14: STUDYID, USUBJID, CPTESTCD, CPSPEC, VISITNUM, CPTPTREF, CPTPTNUM
A15: CV | B15: Cardiovascular System Findings | C15: One record per finding or result per time point per visit per subject | D15: cv.sas | E15: Findings | G15: STUDYID, USUBJID, VISITNUM, CVTESTCD, CVTPTREF, CVTPTNUM | H15: STUDYID, USUBJID, VISITNUM, CVTESTCD, CVTPTREF, CVTPTNUM
A16: DA | B16: Product Accountability | C16: One record per product accountability finding per subject | D16: da.sas | E16: Findings | G16: STUDYID, USUBJID, DATESTCD, DADTC | H16: STUDYID, USUBJID, DATESTCD, DADTC
A17: DD | B17: Death Details | C17: One record per finding per subject | D17: dd.sas | E17: Findings | G17: STUDYID, USUBJID, DDTESTCD, DDDTC | H17: STUDYID, USUBJID, DDTESTCD, DDDTC
A18: DM | B18: Demographics | C18: One record per subject | D18: dm.sas | E18: Special Purpose | G18: STUDYID, USUBJID | H18: STUDYID, USUBJID
... A68: VS | B68: Vital Signs | C68: One record per vital sign measurement per time point per visit per subject | D68: vs.sas | E68: Findings | G68: STUDYID, USUBJID, VSTESTCD, VISITNUM, VSTPTREF, VSTPTNUM | H68: STUDYID, USUBJID, VSTESTCD, VISITNUM, VSTPTREF, VSTPTNUM
A69: SUPP-- | B69: Supplemental Qualifiers for [domain name] | C69: One record per supplemental qualifier per related parent domain record(s) | E69: Relationship | G69: STUDYID, RDOMAIN, USUBJID, IDVAR, IDVARVAL, QNAM | H69: STUDYID, RDOMAIN, USUBJID, IDVAR, IDVARVAL, QNAM
A71: CODELIST
A73: 重要提示:
A74: (1) 请根据项目的具体情况选择合适的SDTM域，并按照需要添加相应的补充数据集(SUPP--)。蓝色斜体字体可根据项目的具体信息进行修改。
A75: (2) SDTM域必须以字母顺序列出(相应的补充数据集应该在SDTM域之后立即进行)。
A76: (3) 一个SDTM域一个表格,即使是多个数据源。
A77: (4) SDTM域必须以.xpt格式生成。
A78: (5) 每个SDTM域中，请按照项目的具体需求选择合适的变量。其中，核心类别为"必需"的变量必须保留。（注：SDTMIG3.3及以后版本对于各个域均增加了EPOCH变量，可按需添加）
A79: (6) 所有__CAT, __SCAT 和 DSDECOD变量的值都要大写。
A80: (7) 如果筛选失败受试者收集了DM信息则也要保留其数据。

Sheet Revision History
A1: Version | B1: Date | C1: Domain(s) | D1: Variable(s) | E1: Modification Details
A2: 1.0 | B2: 45657 | C2: NA | D2: NA | E2: Initial Version

Sheet CODELIST
A1: Control Terminology | I1: CRF
A2: Domain | B2: ID | C2: Name | D2: NCI_Codelist_Code | E2: Datatype | F2: Term | G2: NCI_Term_Code | H2: Decode | I2: CRF Term
I3: Please ref to CDISC SDTM CT

Sheet AE
A1: AE Domain Mapping Specifications
A2: 方案编号: | D2: =CONTENT!$B$3 -> XXXXX
A3: SDTM 版本: | D3: =CONTENT!$B$4 -> 3.4
A4: SDTM 数据集描述: | D4: =CONTENT!$B$7 -> Adverse Events
A5: SDTM 数据集结构: | D5: =CONTENT!$C$7 -> One record per adverse event per subject
A6: 程序名称: | D6: =CONTENT!$D$7 -> ae.sas
A7: 常规观测分类: | D7: =CONTENT!$E$7 -> Events
A8: 数据来源: | D8: =CONTENT!$F$7 -> 0
A9: 关键变量: | D9: =CONTENT!$G$7 -> STUDYID, USUBJID, AEDECOD, AESTDTC
A10: 排序变量: | D10: =CONTENT!$G$7 -> STUDYID, USUBJID, AEDECOD, AESTDTC
A11: 提取规则: | D11: =CONTENT!$I$7 -> 0
A13: Variable Name | B13: Variable Label | C13: Type | D13: Length | E13: Controlled Terms, Codelist or Format | F13: Source | G13: Core | H13: Transformation definition | I13: Variable Type | J13: Variable Order | K13: CDISC Notes
A14: STUDYID | B14: Study Identifier | C14: Char | D14: 20 | F14: Assigned | G14: 必需 | I14: SDTM | J14: =ROW()-13 -> 1 | K14: Unique identifier for a study.
A15: DOMAIN | B15: Domain Abbreviation | C15: Char | D15: 2 | E15: AE | F15: Assigned | G15: 必需 | H15: AE | I15: SDTM | J15: =ROW()-13 -> 2 | K15: Two-character abbreviation for the domain.
A16: USUBJID | B16: Unique Subject Identifier | C16: Char | D16: 30 | F16: Derived | G16: 必需 | I16: SDTM | J16: =ROW()-13 -> 3 | K16: Identifier used to uniquely identify a subject across all studies for all applications or submissions involving the product.
A17: SPDEVID | B17: Sponsor Device Identifier | C17: Char | D17: 25 | F17: Assigned | G17: 可有 | I17: SDTM | J17: 4 | K17: A sequence of characters used by the sponsor to uniquely identify a specific device. Used to represent a device associated in some way with the adverse event. SPDEVID values are defined in the Device Identifiers (DI) domain.
A18: AESEQ | B18: Sequence Number | C18: Num | F18: Derived | G18: 必需 | I18: SDTM | J18: =ROW()-13 -> 5 | K18: Sequence number given to ensure uniqueness of subject records within a domain. May be any valid number.
A19: AEGRPID | B19: Group ID | C19: Char | D19: 25 | F19: CRF | G19: 可有 | I19: SDTM | J19: =ROW()-13 -> 6 | K19: Used to tie together a block of related records in a single domain for a subject.
A20: AEREFID | B20: Reference ID | C20: Char | D20: 25 | F20: CRF | G20: 可有 | I20: SDTM | J20: =ROW()-13 -> 7 | K20: Internal or external identifier such as a serial number on an SAE reporting form.
A21: AESPID | B21: Sponsor-Defined Identifier | C21: Char | D21: 25 | F21: CRF | G21: 可有 | I21: SDTM | J21: =ROW()-13 -> 8 | K21: Sponsor-defined identifier. It may be preprinted on the CRF as an explicit line identifier or defined in the sponsor's operational database. Example: Line number on an Adverse Events CRF page.
A22: AETERM | B22: Reported Term for the Adverse Event | C22: Char | D22: 200 | F22: CRF | G22: 必需 | I22: SDTM | J22: =ROW()-13 -> 9 | K22: Verbatim name of the event.
A23: AEMODIFY | B23: Modified Reported Term | C23: Char | D23: 200 | F23: Assigned | G23: 可有 | I23: SDTM | J23: =ROW()-13 -> 10 | K23: If AETERM is modified to facilitate coding, then AEMODIFY will contain the modified text.
A24: AELLT | B24: Lowest Level Term | C24: Char | D24: 200 | E24: MedDRA | F24: Assigned | G24: 期望 | I24: SDTM | J24: =ROW()-13 -> 11 | K24: Dictionary-derived text description of the lowest level term.
A25: AELLTCD | B25: Lowest Level Term Code | C25: Num | E25: MedDRA | F25: Assigned | G25: 期望 | I25: SDTM | J25: =ROW()-13 -> 12 | K25: Dictionary-derived code for the lowest level term.
A26: AEDECOD | B26: Dictionary-Derived Term | C26: Char | D26: 200 | E26: MedDRA | F26: Assigned | G26: 必需 | I26: SDTM | J26: =ROW()-13 -> 13 | K26: Dictionary-derived text description of AETERM or AEMODIFY. Equivalent to the Preferred Term (PT in MedDRA). The sponsor is expected to provide the dictionary name and version used to map the terms utilizing the external codelist element in the Define-XML document.
A27: AEPTCD | B27: Preferred Term Code | C27: Num | E27: MedDRA | F27: Assigned | G27: 期望 | I27: SDTM | J27: =ROW()-13 -> 14 | K27: Dictionary-derived code for the preferred term.
A28: AEHLT | B28: High Level Term | C28: Char | D28: 200 | E28: MedDRA | F28: Assigned | G28: 期望 | I28: SDTM | J28: =ROW()-13 -> 15 | K28: Dictionary-derived text description of the high level term for the primary system organ class (SOC).
A29: AEHLTCD | B29: High Level Term Code | C29: Num | E29: MedDRA | F29: Assigned | G29: 期望 | I29: SDTM | J29: =ROW()-13 -> 16 | K29: Dictionary-derived code for the high level term for the primary SOC.
A30: AEHLGT | B30: High Level Group Term | C30: Char | D30: 200 | E30: MedDRA | F30: Assigned | G30: 期望 | I30: SDTM | J30: =ROW()-13 -> 17 | K30: Dictionary-derived text description of the high level group term for the primary SOC.
A31: AEHLGTCD | B31: High Level Group Term Code | C31: Num | E31: MedDRA | F31: Assigned | G31: 期望 | I31: SDTM | J31: =ROW()-13 -> 18 | K31: Dictionary-derived code for the high level group term for the primary SOC.
A32: AECAT | B32: Category for Adverse Event | C32: Char | D32: 100 | E32: * | F32: Assigned | G32: 可有 | I32: SDTM | J32: =ROW()-13 -> 19 | K32: Used to define a category of related records. Examples: "BLEEDING", "NEUROPSYCHIATRIC".
A33: AESCAT | B33: Subcategory for Adverse Event | C33: Char | D33: 100 | E33: * | F33: Assigned | G33: 可有 | I33: SDTM | J33: =ROW()-13 -> 20 | K33: A further categorization of adverse event. Example: "NEUROLOGIC".
A34: AEPRESP | B34: Pre-Specified Adverse Event | C34: Char | D34: 1 | E34: (NY) | F34: Derived | G34: 可有 | I34: SDTM | J34: =ROW()-13 -> 21 | K34: A value of "Y" indicates that this adverse event was prespecified on the CRF. Values are null for spontaneously reported events (i.e., those collected as free-text verbatim terms).
A35: AEBODSYS | B35: Body System or Organ Class | C35: Char | D35: 200 | E35: * | F35: Assigned | G35: 期望 | I35: SDTM | J35: =ROW()-13 -> 22 | K35: Dictionary derived. Body system or organ class used by the sponsor from the coding dictionary (e.g., MedDRA). When using a multi-axial dictionary such as MedDRA, this should contain the SOC used for the sponsor's analyses and summary tables, which may not necessarily be the primary SOC.
A36: AEBDSYCD | B36: Body System or Organ Class Code | C36: Num | E36: MedDRA | F36: Assigned | G36: 期望 | I36: SDTM | J36: =ROW()-13 -> 23 | K36: Dictionary derived. Code for the body system or organ class used by the sponsor. When using a multi-axial dictionary such as MedDRA, this should contain the SOC used for the sponsor's analyses and summary tables, which may not necessarily be the primary SOC.
A37: AESOC | B37: Primary System Organ Class | C37: Char | D37: 200 | E37: MedDRA | F37: Assigned | G37: 期望 | I37: SDTM | J37: =ROW()-13 -> 24 | K37: Dictionary-derived text description of the primary SOC. Will be the same as AEBODSYS if the primary SOC was used for analysis.
A38: AESOCCD | B38: Primary System Organ Class Code | C38: Num | E38: MedDRA | F38: Assigned | G38: 期望 | I38: SDTM | J38: =ROW()-13 -> 25 | K38: Dictionary-derived code for the primary SOC. Will be the same as AEBDSYCD if the primary SOC was used for analysis.
A39: AELOC | B39: Location of Event | C39: Char | D39: 40 | E39: (LOC) | F39: CRF | G39: 可有 | I39: SDTM | J39: =ROW()-13 -> 26 | K39: Describes anatomical location relevant for the event (e.g., "ARM" for skin rash).
A40: AESEV | B40: Severity/Intensity | C40: Char | D40: 10 | E40: (AESEV) | F40: CRF | G40: 可有 | I40: SDTM | J40: =ROW()-13 -> 27 | K40: The severity or intensity of the event. Examples: "MILD", "MODERATE", "SEVERE".
A41: AESER | B41: Serious Event | C41: Char | D41: 1 | E41: (NY) | F41: CRF | G41: 期望 | I41: SDTM | J41: =ROW()-13 -> 28 | K41: Is this a serious event? Valid values are "Y" and "N".
...

Sheet AG
A1: AG Domain Mapping Specifications
A2: 方案编号: | D2: =CONTENT!$B$3 -> XXXXX
A3: SDTM 版本: | D3: =CONTENT!$B$4 -> 3.4
A4: SDTM 数据集描述: | D4: =CONTENT!$B$8 -> Procedure Agents
A5: SDTM 数据集结构: | D5: =CONTENT!$C$8 -> One record per recorded intervention occurrence per subject
A6: 程序名称: | D6: =CONTENT!$D$8 -> ag.sas
A7: 常规观测分类: | D7: =CONTENT!$E$8 -> Interventions
A8: 数据来源: | D8: =CONTENT!$F$8 -> 0
A9: 关键变量: | D9: =CONTENT!$G$8 -> STUDYID, USUBJID,AGGRPID, AGSPID, AGTRT
A10: 排序变量: | D10: =CONTENT!$H$8 -> STUDYID, USUBJID,AGGRPID, AGSPID, AGTRT
A11: 提取规则: | D11: =CONTENT!$I$8 -> 0
A13: Variable Name | B13: Variable Label | C13: Type | D13: Length | E13: Controlled Terms, Codelist or Format | F13: Source | G13: Core | H13: Transformation definition | I13: Variable Type | J13: Variable Order | K13: CDISC Notes
A14: STUDYID | B14: Study Identifier | C14: Char | D14: 20 | F14: Assigned | G14: 必需 | I14: SDTM | J14: 1 | K14: Unique identifier for a study.
A15: DOMAIN | B15: Domain Abbreviation | C15: Char | D15: 2 | E15: AG | F15: Assigned | G15: 必需 | H15: AG | I15: SDTM | J15: 2 | K15: Two-character abbreviation for the domain.
A16: USUBJID | B16: Unique Subject Identifier | C16: Char | D16: 30 | F16: Derived | G16: 必需 | I16: SDTM | J16: 3 | K16: Identifier used to uniquely identify a subject across all studies for all applications or submissions involving the product.
A17: AGSEQ | B17: Sequence Number | C17: Num | F17: Derived | G17: 必需 | I17: SDTM | J17: 4 | K17: Sequence number given to ensure uniqueness of subject records within a domain. May be any valid number.
A18: AGGRPID | B18: Group ID | C18: Char | D18: 25 | F18: CRF | G18: 可有 | I18: SDTM | J18: 5 | K18: Used to tie together a block of related records in a single domain for a subject.
A19: AGSPID | B19: Sponsor-Defined Identifier | C19: Char | D19: 25 | F19: CRF | G19: 可有 | I19: SDTM | J19: 6 | K19: Sponsor-defined reference number. May be preprinted on the CRF as an explicit line identifier or defined in the sponsor's operational database. Example: Line number from the procedure or test page.
A20: AGLNKID | B20: Link ID | C20: Char | D20: 25 | F20: CRF | G20: 可有 | I20: SDTM | J20: 7 | K20: Identifier used to link related records across domains.This may be a one-to-one or a one-to-many relationship.
A21: AGLNKGRP | B21: Link Group ID | C21: Char | D21: 25 | F21: CRF | G21: 可有 | I21: SDTM | J21: 8 | K21: Identifier used to link related records across domains.This will usually be a many-to-one relationship.
A22: AGTRT | B22: Reported Agent Name | C22: Char | D22: 200 | F22: CRF | G22: 必需 | I22: SDTM | J22: 9 | K22: Verbatim medication name that is either preprinted or collected on a CRF.
A23: AGMODIFY | B23: Modified Reported Name | C23: Char | D23: 200 | F23: Assigned | G23: 可有 | I23: SDTM | J23: 10 | K23: If AGTRT is modified to facilitate coding, then AGMODIFY will contain the modified text.
A24: AGDECOD | B24: Standardized Agent Name | C24: Char | D24: 200 | E24: * | F24: Assigned | G24: 可有 | I24: SDTM | J24: 11 | K24: Standardized or dictionary-derived text description of AGTRT or AGMODIFY. Equivalent to the generic medication name in WHO Drug. The sponsor is expected to provide the dictionary name and version used to map the terms utilizing the external codelist element in the Define-XML document. If an intervention term does not have a decode value in the dictionary, then AGDECOD will be left blank.
A25: AGCAT | B25: Category for Agent | C25: Char | D25: 100 | E25: * | F25: Assigned | G25: 可有 | I25: SDTM | J25: 12 | K25: Used to define a category of agent. Examples: "CHALLENGE AGENT", "PET TRACER".
A26: AGSCAT | B26: Subcategory for Agent | C26: Char | D26: 100 | E26: * | F26: Assigned | G26: 可有 | I26: SDTM | J26: 13 | K26: Further categorization of agent.
A27: AGPRESP | B27: AG Pre-Specified | C27: Char | D27: 1 | E27: (NY) | F27: Assigned | G27: 可有 | I27: SDTM | J27: 14 | K27: Used to indicate whether ("Y"/null) information about the use of a specific agent was solicited on the CRF.
A28: AGOCCUR | B28: AG Occurrence | C28: Char | D28: 1 | E28: (NY) | F28: CRF | G28: 可有 | I28: SDTM | J28: 15 | K28: When the use of specific agent is solicited, AGOCCUR is used to indicate whether ("Y"/"N") use of the agent occurred. Values are null for agents not specifically solicited.
A29: AGSTAT | B29: Completion Status | C29: Char | D29: 8 | E29: (ND) | F29: CRF | G29: 可有 | I29: SDTM | J29: 16 | K29: Used to indicate that a question about a prespecified agent was not answered. Should be null or have a value of "NOT DONE".
A30: AGREASND | B30: Reason Procedure Agent Not Collected | C30: Char | D30: 200 | F30: CRF | G30: 可有 | I30: SDTM | J30: 17 | K30: Describes the reason a response to a question about the occurrence of a procedure agent was not collected. Used in conjunction with AGSTAT when value is "NOT DONE".
A31: AGCLAS | B31: Agent Class | C31: Char | D31: 200 | E31: * | F31: Assigned | G31: 可有 | I31: SDTM | J31: 18 | K31: Drug class. May be obtained from coding. When coding to a single class, populate with class value. If using a dictionary and coding to multiple classes, follow guidance in Section 4.2.8.3, Multiple Values for a Non-result Qualifier Variable, or omit AGCLAS.
A32: AGCLASCD | B32: Agent Class Code | C32: Char | D32: 200 | E32: * | F32: Assigned | G32: 可有 | I32: SDTM | J32: 19 | K32: Class code corresponding to AGCLAS. Drug class. May be obtained from coding. When coding to a single class, populate with class code. If using a dictionary and coding to multiple classes, follow guidance in Section 4.2.8.3, Multiple Values for a Non-result Qualifier Variable, or omit AGCLASCD.
A33: AGDOSE | B33: Dose per Administration | C33: Num | F33: CRF | G33: 可有 | I33: SDTM | J33: 20 | K33: Amount of AGTRT taken.
A34: AGDOSTXT | B34: Dose Description | C34: Char | D34: 100 | F34: CRF | G34: 可有 | I34: SDTM | J34: 21 | K34: Dosing amounts or a range of dosing information collected in text form. Units may be stored in AGDOSU. Examples: "200-400", "15-20".
A35: AGDOSU | B35: Dose Units | C35: Char | D35: 20 | E35: (UNIT) | F35: CRF | G35: 可有 | I35: SDTM | J35: 22 | K35: Units for AGDOSE and AGDOSTXT. Examples: "ng", "mg", "mg/kg".
A36: AGDOSFRM | B36: Dose Form | C36: Char | D36: 20 | E36: (FRM) | F36: CRF | G36: 可有 | I36: SDTM | J36: 23 | K36: Dose form for AGTRT. Examples: "TABLET", "AEROSOL".
A37: AGDOSFRQ | B37: Dosing Frequency per Interval | C37: Char | D37: 20 | E37: (FREQ) | F37: CRF | G37: 可有 | I37: SDTM | J37: 24 | K37: Usually expressed as the number of repeated administrations of AGDOSE within a specific time period. Example: "ONCE".
A38: AGROUTE | B38: Route of Administration | C38: Char | D38: 20 | E38: (ROUTE) | F38: CRF | G38: 可有 | I38: SDTM | J38: 25 | K38: Route of administration for AGTRT. Example: "ORAL".
A39: VISITNUM | B39: Visit Number | C39: Num | F39: Assigned | G39: 期望 | I39: SDTM | J39: 26 | K39: 1. Clinical encounter number. \n 2. Numeric version of VISIT, used for sorting.
A40: VISIT | B40: Visit Name | C40: Char | D40: 100 | F40: Assigned | G40: 可有 | I40: SDTM | J40: 27 | K40: 1. Protocol-defined description of clinical encounter. \n 2. May be used in addition to VISITNUM and/or VISITDY.
A41: VISITDY | B41: Planned Study Day of Visit | C41: Num | F41: Assigned | G41: 可有 | I41: SDTM | J41: 28 | K41: Planned study day of the visit based upon RFSTDTC in Demographics.
...

Sheet BE
A1: BE Domain Mapping Specifications
A2: 方案编号: | D2: =CONTENT!$B$3 -> XXXXX
A3: SDTM 版本: | D3: =CONTENT!$B$4 -> 3.4
A4: SDTM 数据集描述: | D4: =CONTENT!$B$9 -> Biospecimen Events
A5: SDTM 数据集结构: | D5: =CONTENT!$C$9 -> One record per instance per biospecimen event per biospecimen identifier per subject
A6: 程序名称: | D6: =CONTENT!$D$9 -> be.sas
A7: 常规观测分类: | D7: =CONTENT!$E$9 -> Events
A8: 数据来源: | D8: =CONTENT!$F$9 -> 0
A9: 关键变量: | D9: =CONTENT!$G$9 -> STUDYID, USUBJID, BEREFID, BETERM, BESDTC
A10: 排序变量: | D10: =CONTENT!$H$9 -> STUDYID, USUBJID, BEREFID, BETERM, BESDTC
A11: 提取规则: | D11: =CONTENT!$I$9 -> 0
A13: Variable Name | B13: Variable Label | C13: Type | D13: Length | E13: Controlled Terms, Codelist or Format | F13: Source | G13: Core | H13: Transformation definition | I13: Variable Type | J13: Variable Order | K13: CDISC Notes
A14: STUDYID | B14: Study Identifier | C14: Char | D14: 20 | F14: Assigned | G14: 必需 | I14: SDTM | J14: 1 | K14: Unique identifier for a study.
A15: DOMAIN | B15: Domain Abbreviation | C15: Char | D15: 2 | E15: BE | F15: Assigned | G15: 必需 | H15: BE | I15: SDTM | J15: 2 | K15: Two-character abbreviation for the domain.
A16: USUBJID | B16: Unique Subject Identifier | C16: Char | D16: 30 | F16: Derived | G16: 必需 | I16: SDTM | J16: 3 | K16: Identifier used to uniquely identify a subject across all studies for all applications or submissions involving the product.
A17: SPDEVID | B17: Sponsor Device Identifier | C17: Char | D17: 25 | F17: Assigned | G17: 可有 | I17: SDTM | J17: 4 | K17: Sponsor-defined identifier for a device.
A18: BESEQ | B18: Sequence Number | C18: Num | F18: Derived | G18: 必需 | I18: SDTM | J18: 5 | K18: Sequence number to ensure uniqueness of records within a dataset for a subject. May be any valid number (including decimals) and does not have to start at 1.
A19: BEGRPID | B19: Group ID | C19: Char | D19: 25 | F19: CRF | G19: 可有 | I19: SDTM | J19: 6 | K19: Optional group identifier, used to link together a block of related records within a subject in a domain.
A20: BEREFID | B20: Reference ID | C20: Char | D20: 25 | F20: CRF | G20: 期望 | I20: SDTM | J20: 7 | K20: Internal or external identifier for the specimen affected or created by the event.
A21: BESPID | B21: Sponsor-Defined Identifier | C21: Char | D21: 25 | F21: CRF | G21: 可有 | I21: SDTM | J21: 8 | K21: Optional sponsor-defined reference number. Example: Line number on a CRF page.
A22: BETERM | B22: Reported Term for the Biospecimen Event | C22: Char | D22: 200 | F22: CRF | G22: 必需 | I22: SDTM | J22: 9 | K22: Topic variable for an event observation, which is the verbatim or pre-specified name of the event.
A23: BEMODIFY | B23: Modified Reported Term | C23: Char | D23: 200 | F23: Assigned | G23: 可有 | I23: SDTM | J23: 10 | K23: If the value for BETERM is modified for coding purposes, then the modified text is placed here.
A24: BEDECOD | B24: Dictionary-Derived Term | C24: Char | D24: 200 | E24: (BEDECOD) | F24: Assigned | G24: 可有 | I24: SDTM | J24: 11 | K24: Dictionary-derived text description of BETERM or BEMODIFY, if applicable.
A25: BECAT | B25: Category for Biospecimen Event | C25: Char | D25: 100 | F25: Assigned | G25: 可有 | I25: SDTM | J25: 12 | K25: Used to define a category of topic-variable values. Example: COLLECTION, PREPARATION, TRANSPORT.
A26: BESCAT | B26: Subcategory for Biospecimen Event | C26: Char | D26: 100 | F26: Assigned | G26: 可有 | I26: SDTM | J26: 13 | K26: A further categorization of BECAT values.
A27: BELOC | B27: Anatomical Location of Event | C27: Char | D27: 40 | E27: (LOC) | F27: CRF | G27: 可有 | I27: SDTM | J27: 14 | K27: Describes the anatomical location relevant for the event (e.g. BRAIN, LUNG).
A28: BEPARTY | B28: Accountable Party | C28: Char | D28: 100 | E28: * | F28: Assigned | G28: 可有 | I28: SDTM | J28: 15 | K28: Party accountable for the transferable object (e.g. specimen) as a result of the activity performed in the associated BETERM variable. The party could be an individual (e.g., subject), an organization (e.g., sponsor), or a location that is a proxy for an individual or organization (e.g., site). It is usually a somewhat general term that is further identified in the BEPRTYID variable.
A29: BEPRTYID | B29: Identification of Accountable Party | C29: Char | D29: 100 | F29: Assigned | G29: 可有 | I29: SDTM | J29: 16 | K29: Identification of the specific party accountable for the transferable object (e.g. Specimen) after the action in BETERM is taken. Used in conjunction with BEPARTY.
A30: VISITNUM | B30: Visit Number | C30: Num | F30: Assigned | G30: 期望 | I30: SDTM | J30: 17 | K30: Clinical encounter number. Numeric version of VISIT, used for sorting.
A31: VISIT | B31: Visit Name | C31: Char | D31: 100 | F31: Assigned | G31: 可有 | I31: SDTM | J31: 18 | K31: Protocol-defined description of clinical encounter.
A32: VISITDY | B32: Planned Study Day of Visit | C32: Num | F32: Assigned | G32: 可有 | I32: SDTM | J32: 19 | K32: Planned study day of VISIT. Should be an integer.
A33: BEDTC | B33: Date/Time of Specimen Collection | C33: Char | D33: 20 | E33: ISO 8601 | F33: CRF | G33: 期望 | I33: SDTM | J33: 20 | K33: Date and time of specimen collection.
A34: BESTDTC | B34: Start Date/Time of Biospecimen Event | C34: Char | D34: 20 | E34: ISO 8601 | F34: CRF | G34: 期望 | I34: SDTM | J34: 21 | K34: Start date/time of the event.
A35: BEENDTC | B35: End Date/Time of Biospecimen Event | C35: Char | D35: 20 | E35: ISO 8601 | F35: CRF | G35: 期望 | I35: SDTM | J35: 22 | K35: End date/time of the event.
A36: BESTDY | B36: Study Day of Start of Biospecimen Event | C36: Num | F36: Derived | G36: 可有 | I36: SDTM | J36: 23 | K36: Actual study day of start of observation expressed in integer days relative to the sponsor-defined RFSTDTC in Demographics.
A37: BEENDY | B37: Study Day of End of Biospecimen Event | C37: Num | F37: Derived | G37: 可有 | I37: SDTM | J37: 24 | K37: Actual study day of end of observation expressed in integer days relative to the sponsor-defined RFSTDTC in Demographics.
A38: BEDUR | B38: Duration of Biospecimen Event | C38: Char | D38: 20 | E38: ISO 8601 | F38: CRF | G38: 可有 | I38: SDTM | J38: 25 | K38: Collected duration and unit of a biospecimen event. Used only if collected on the CRF and not derived from start and end date/times. Example: P1DT2H (for 1 day, 2 hours).
A42: CONTENT

Sheet BS
A1: BS Domain Mapping Specifications
A2: 方案编号: | D2: =CONTENT!$B$3 -> XXXXX
A3: SDTM 版本: | D3: =CONTENT!$B$4 -> 3.4
A4: SDTM 数据集描述: | D4: =CONTENT!$B$10 -> Biospecimen Findings
A5: SDTM 数据集结构: | D5: =CONTENT!$C$10 -> One record per measurement per biospecimen identifier per subject
A6: 程序名称: | D6: =CONTENT!$D$10 -> bs.sas
A7: 常规观测分类: | D7: =CONTENT!$E$10 -> Findings
A8: 数据来源: | D8: =CONTENT!$F$10 -> 0
A9: 关键变量: | D9: =CONTENT!$G$10 -> STUDYID, USUBJID, BSREFID, BSTESTCD
A10: 排序变量: | D10: =CONTENT!$H$10 -> STUDYID, USUBJID, BSREFID, BSTESTCD
A11: 提取规则: | D11: =CONTENT!$I$10 -> 0
A13: Variable Name | B13: Variable Label | C13: Type | D13: Length | E13: Controlled Terms, Codelist or Format | F13: Source | G13: Core | H13: Transformation definition | I13: Variable Type | J13: Variable Order | K13: CDISC Notes
A14: STUDYID | B14: Study Identifier | C14: Char | D14: 20 | F14: Assigned | G14: 必需 | I14: SDTM | J14: 1 | K14: Unique identifier for a study.
A15: DOMAIN | B15: Domain Abbreviation | C15: Char | D15: 2 | E15: BS | F15: Assigned | G15: 必需 | H15: BS | I15: SDTM | J15: 2 | K15: Two-character abbreviation for the domain.
A16: USUBJID | B16: Unique Subject Identifier | C16: Char | D16: 30 | F16: Derived | G16: 必需 | I16: SDTM | J16: 3 | K16: Identifier used to uniquely identify a subject across all studies for all applications or submissions involving the product.
A17: SPDEVID | B17: Sponsor Device Identifier | C17: Char | D17: 25 | F17: Assigned | G17: 可有 | I17: SDTM | J17: 4 | K17: Sponsor-defined identifier for a device.
A18: BSSEQ | B18: Sequence Number | C18: Num | F18: Derived | G18: 必需 | I18: SDTM | J18: 5 | K18: Sequence number given to ensure uniqueness within a dataset for a subject. May be any valid number (including decimals) and does not have to start at 1.
A19: BSGRPID | B19: Group ID | C19: Char | D19: 25 | F19: CRF | G19: 可有 | I19: SDTM | J19: 6 | K19: Optional group identifier, used to link together a block of related records within a subject in a domain.
A20: BSREFID | B20: Reference ID | C20: Char | D20: 25 | F20: CRF | G20: 期望 | I20: SDTM | J20: 7 | K20: Internal or external identifier such as lab specimen ID.
A21: BSSPID | B21: Sponsor-Defined Identifier | C21: Char | D21: 25 | F21: CRF | G21: 可有 | I21: SDTM | J21: 8 | K21: Sponsor-defined identifier.
A22: BSTESTCD | B22: Biospecimen Test Short Name | C22: Char | D22: 8 | E22: (BSTESTCD) | F22: Assigned | G22: 必需 | I22: SDTM | J22: 9 | K22: Short character value for BSTEST used as a column name when converting a dataset from a vertical format to a horizontal format. The short value can be up to 8 characters. Examples: VOLUME, RIN.
A23: BSTEST | B23: Biospecimen Test Name | C23: Char | D23: 40 | F23: CRF | G23: 必需 | I23: SDTM | J23: 10 | K23: Long name for BSTESTCD. Examples: Volume, RNA Integrity Number.
A24: BSCAT | B24: Category for Biospecimen Test | C24: Char | D24: 100 | F24: Assigned | G24: 期望 | I24: SDTM | J24: 11 | K24: Used to define a category of topic-variable values. Example: MEASUREMENT, QUALITY.
A25: BSSCAT | B25: Subcategory for Biospecimen Test | C25: Char | D25: 100 | F25: Assigned | G25: 可有 | I25: SDTM | J25: 12 | K25: Used to define a further categorization of BSCAT values.
A26: BSORRES | B26: Result or Finding in Original Units | C26: Char | D26: 200 | F26: CRF | G26: 期望 | I26: SDTM | J26: 13 | K26: Result of the measurement or finding as originally received or collected.
A27: BSORRESU | B27: Original Units | C27: Char | D27: 20 | E27: (UNIT) | F27: CRF | G27: 期望 | I27: SDTM | J27: 14 | K27: Unit for BSORRES. Examples: mg, mL.
A28: BSSTRESC | B28: Character Result/Finding in Std Format | C28: Char | D28: 200 | F28: Derived | G28: 期望 | I28: SDTM | J28: 15 | K28: Contains the result value for all findings, copied or derived from BSORRES in a standard format or standard units. BSSTRESC should store all results or findings in character format; if results are numeric, they should also be stored in numeric format in BSSTRESN.
A29: BSSTRESN | B29: Numeric Result/Finding in Standard Units | C29: Num | F29: Derived | G29: 期望 | I29: SDTM | J29: 16 | K29: Used for continuous or numeric results or findings in standard format; copied in numeric format from BSSTRESC. BSSTRESN should store all numeric test results or findings.
A30: BSSTRESU | B30: Standard Units | C30: Char | D30: 20 | E30: (UNIT) | F30: Assigned | G30: 期望 | I30: SDTM | J30: 17 | K30: Standardized unit used for BSSTRESC and BSSTRESN.
A31: BSSTAT | B31: Completion Status | C31: Char | D31: 8 | E31: (ND) | F31: CRF | G31: 可有 | I31: SDTM | J31: 18 | K31: Used to indicate that a test was not done, or was attempted but did not generate a result. Should be null or have a value of NOT DONE.
A32: BSREASND | B32: Reason Test Not Done | C32: Char | D32: 200 | F32: CRF | G32: 可有 | I32: SDTM | J32: 19 | K32: Reason not done. Used in conjunction with BSSTAT when value is NOT DONE.
A33: BSNAM | B33: Vendor Name | C33: Char | D33: 40 | F33: Assigned | G33: 可有 | I33: SDTM | J33: 20 | K33: Name or identifier of the vendor (e.g., laboratory) that provided the test results.
A34: BSSPEC | B34: Specimen Type | C34: Char | D34: 50 | E34: (SPECTYPE)(GENSMP) | F34: Assigned | G34: 可有 | I34: SDTM | J34: 21 | K34: Defines the type of specimen used for a measurement. Examples: SERUM, PLASMA, URINE, SOFT TISSUE.
A35: BSANTREG | B35: Anatomical Region of Specimen | C35: Char | D35: 100 | E35: * | F35: Assigned | G35: 可有 | I35: SDTM | J35: 22 | K35: Defines the specific anatomical or biological region of a tissue, organ specimen or the region from which the specimen is obtained, as defined in the protocol, such as a section or part of what is described in the BSSPEC variable. Examples: CORTEX, MEDULLA, MUCOSA.
A36: BSSPCCND | B36: Specimen Condition | C36: Char | D36: 50 | E36: (SPECCOND) | F36: CRF | G36: 可有 | I36: SDTM | J36: 23 | K36: Defines the condition of the specimen. Examples: HEMOLYZED, ICTERIC, LIPEMIC.
A37: BSMETHOD | B37: Method of Test or Examination | C37: Char | D37: 100 | E37: (METHOD) | F37: CRF | G37: 可有 | I37: SDTM | J37: 24 | K37: Method of the test or examination. Examples: SPECTROPHOTOMETRY, ELECTROPHORESIS.
A38: BSBLFL | B38: Baseline Flag | C38: Char | D38: 1 | E38: (NY) | F38: Derived | G38: 可有 | I38: SDTM | J38: 25 | K38: Indicator used to identify a baseline value.
A39: VISITNUM | B39: Visit Number | C39: Num | F39: Assigned | G39: 期望 | I39: SDTM | J39: 26 | K39: Clinical encounter number. Numeric version of VISIT, used for sorting.
A40: VISIT | B40: Visit Name | C40: Char | D40: 100 | F40: Assigned | G40: 可有 | I40: SDTM | J40: 27 | K40: Protocol-defined description of clinical encounter.
A41: VISITDY | B41: Planned Study Day of Visit | C41: Num | F41: Assigned | G41: 可有 | I41: SDTM | J41: 28 | K41: Planned study day of VISIT. Should be an integer.
...

Sheet CE
A1: CE Domain Mapping Specifications
A2: 方案编号: | D2: =CONTENT!$B$3 -> XXXXX
A3: SDTM 版本: | D3: =CONTENT!$B$4 -> 3.4
A4: SDTM 数据集描述: | D4: =CONTENT!$B$11 -> Clinical Events
A5: SDTM 数据集结构: | D5: =CONTENT!$C$11 -> One record per event per subject
A6: 程序名称: | D6: =CONTENT!$D$11 -> ce.sas
A7: 常规观测分类: | D7: =CONTENT!$E$11 -> Events
A8: 数据来源: | D8: =CONTENT!$F$11 -> 0
A9: 关键变量: | D9: =CONTENT!$G$11 -> STUDYID, USUBJID, CETERM, CESTDTC
A10: 排序变量: | D10: =CONTENT!$H$11 -> STUDYID, USUBJID, CETERM, CESTDTC
A11: 提取规则: | D11: =CONTENT!$I$11 -> 0
A13: Variable Name | B13: Variable Label | C13: Type | D13: Length | E13: Controlled Terms, Codelist or Format | F13: Source | G13: Core | H13: Transformation definition | I13: Variable Type | J13: Variable Order | K13: CDISC Notes
A14: STUDYID | B14: Study Identifier | C14: Char | D14: 20 | F14: Assigned | G14: 必需 | I14: SDTM | J14: =ROW()-13 -> 1 | K14: Unique identifier for a study.
A15: DOMAIN | B15: Domain Abbreviation | C15: Char | D15: 2 | E15: CE | F15: Assigned | G15: 必需 | H15: CE | I15: SDTM | J15: =ROW()-13 -> 2 | K15: Two-character abbreviation for the domain.
A16: USUBJID | B16: Unique Subject Identifier | C16: Char | D16: 30 | F16: Derived | G16: 必需 | I16: SDTM | J16: =ROW()-13 -> 3 | K16: Identifier used to uniquely identify a subject across all studies for all applications or submissions involving the product.
A17: CESEQ | B17: Sequence Number | C17: Num | F17: Derived | G17: 必需 | I17: SDTM | J17: =ROW()-13 -> 4 | K17: Sequence number given to ensure uniqueness of subject records within a domain. May be any valid number.
A18: CEGRPID | B18: Group ID | C18: Char | D18: 25 | F18: CRF | G18: 可有 | I18: SDTM | J18: =ROW()-13 -> 5 | K18: Used to link together a block of related records for a subject within a domain.
A19: CEREFID | B19: Reference ID | C19: Char | D19: 25 | F19: CRF | G19: 可有 | I19: SDTM | J19: =ROW()-13 -> 6 | K19: Internal or external identifier (e.g., lab specimen ID, UUID for an ECG waveform or medical image).
A20: CESPID | B20: Sponsor-Defined Identifier | C20: Char | D20: 25 | F20: CRF | G20: 可有 | I20: SDTM | J20: =ROW()-13 -> 7 | K20: Sponsor-defined identifier.
A21: CETERM | B21: Reported Term for the Clinical Event | C21: Char | D21: 200 | F21: CRF | G21: 必需 | I21: SDTM | J21: =ROW()-13 -> 8 | K21: Term for the medical condition or event. Most likely preprinted on CRF.
A22: CEDECOD | B22: Dictionary-Derived Term | C22: Char | D22: 200 | E22: * | F22: Assigned | G22: 可有 | I22: SDTM | J22: =ROW()-13 -> 9 | K22: Controlled terminology for the name of the clinical event. The sponsor is expected to provide the dictionary name and version used to map the terms utilizing the external codelist element in the Define-XML document.
A23: CECAT | B23: Category for the Clinical Event | C23: Char | D23: 100 | E23: * | F23: Assigned | G23: 可有 | I23: SDTM | J23: =ROW()-13 -> 10 | K23: Used to define a category of related records.
A24: CESCAT | B24: Subcategory for the Clinical Event | C24: Char | D24: 100 | E24: * | F24: Assigned | G24: 可有 | I24: SDTM | J24: =ROW()-13 -> 11 | K24: A further categorization of the condition or event.
A25: CEPRESP | B25: Clinical Event Pre-specified | C25: Char | D25: 1 | E25: (NY) | F25: Assigned | G25: 可有 | I25: SDTM | J25: =ROW()-13 -> 12 | K25: Used to indicate whether the event in CETERM was prespecified. Value is "Y" for prespecified events and null for spontaneously reported events.
A26: CEOCCUR | B26: Clinical Event Occurrence | C26: Char | D26: 1 | E26: (NY) | F26: CRF | G26: 可有 | I26: SDTM | J26: =ROW()-13 -> 13 | K26: Used when the occurrence of specific events is solicited, to indicate whether or not a clinical event occurred. Values are null for spontaneously reported events.
A27: CESTAT | B27: Completion Status | C27: Char | D27: 8 | E27: (ND) | F27: CRF | G27: 可有 | I27: SDTM | J27: =ROW()-13 -> 14 | K27: The status indicates that a question from a prespecified list was not answered.
A28: CEREASND | B28: Reason Clinical Event Not Collected | C28: Char | D28: 200 | F28: CRF | G28: 可有 | I28: SDTM | J28: =ROW()-13 -> 15 | K28: Describes the reason clinical event data was not collected. Used in conjunction with CESTAT when value is "NOT DONE".
A29: CEBODSYS | B29: Body System or Organ Class | C29: Char | D29: 200 | E29: * | F29: Assigned | G29: 可有 | I29: SDTM | J29: =ROW()-13 -> 16 | K29: Dictionary-derived. Body system or organ class that is involved in an event or measurement from a standard hierarchy (e.g., MedDRA). When using a multi-axial dictionary such as MedDRA, this should contain the SOC used for the sponsor's analyses and summary tables, which may not necessarily be the primary SOC.
A30: CESEV | B30: Severity/Intensity | C30: Char | D30: 10 | E30: (SEVRS) | F30: CRF | G30: 可有 | I30: SDTM | J30: =ROW()-13 -> 17 | K30: The severity or intensity of the event. Examples: "MILD", "MODERATE", "SEVERE".
A31: CETOXGR | B31: Standard Toxicity Grade | C31: Char | D31: 20 | E31: * | F31: CRF | G31: 可有 | I31: SDTM | J31: =ROW()-13 -> 18 | K31: Toxicity grade according to a standard toxicity scale (e.g., Common Terminology Criteria for Adverse Events (CTCAE) v3.0). Sponsor should specify name of the scale and version used in the metadata. If value is from a numeric scale, represent only the number (e.g., "2", not "Grade 2").
A32: TAETORD | B32: Planned Order of Element within Arm | C32: Num | F32: Assigned | G32: 可有 | I32: SDTM | J32: =ROW()-13 -> 19 | K32: Number that gives the planned order of the element within the arm for the element in which the clinical event started.
A33: EPOCH | B33: Epoch | C33: Char | D33: 100 | E33: (EPOCH) | F33: Assigned | G33: 可有 | I33: SDTM | J33: =ROW()-13 -> 20 | K33: Epoch associated with the start date/time of the clinical event.
A34: CEDTC | B34: Date/Time of Event Collection | C34: Char | D34: 20 | E34: ISO 8601 | F34: CRF | G34: 可有 | I34: SDTM | J34: =ROW()-13 -> 21 | K34: Collection date and time for the clinical event observation represented in ISO 8601 character format.
A35: CESTDTC | B35: Start Date/Time of Clinical Event | C35: Char | D35: 20 | E35: ISO 8601 | F35: CRF | G35: 可有 | I35: SDTM | J35: =ROW()-13 -> 22 | K35: Start date/time of the clinical event represented in ISO 8601 character format.
A36: CEENDTC | B36: End Date/Time of Clinical Event | C36: Char | D36: 20 | E36: ISO 8601 | F36: CRF | G36: 可有 | I36: SDTM | J36: =ROW()-13 -> 23 | K36: End date/time of the clinical event, represented in ISO 8601 character format.
A37: CEDY | B37: Study Day of Event Collection | C37: Num | F37: Derived | G37: 可有 | I37: SDTM | J37: =ROW()-13 -> 24 | K37: Study day of clinical event collection, measured as integer days. Algorithm for calculations must be relative to the sponsor-defined RFSTDTC variable in Demographics. This formula should be consistent across the submission.
A38: CESTDY | B38: Study Day of Start of Event | C38: Num | F38: Derived | G38: 可有 | I38: SDTM | J38: =ROW()-13 -> 25 | K38: Actual study day of start of the clinical event expressed in integer days relative to the sponsor-defined RFSTDTC in Demographics.
A39: CEENDY | B39: Study Day of End of Event | C39: Num | F39: Derived | G39: 可有 | I39: SDTM | J39: =ROW()-13 -> 26 | K39: Actual study day of end of the clinical event expressed in integer days relative to the sponsor-defined RFSTDTC in Demographics.
A40: CESTRF | B40: Start Relative to Reference Period | C40: Char | D40: 20 | E40: (STENRF) | F40: Derived | G40: 可有 | I40: SDTM | J40: =ROW()-13 -> 27 | K40: Describes the start of the clinical event relative to the sponsor-defined reference period. The sponsor-defined reference period is a continuous period of time defined by a discrete starting point and a discrete ending point (represented by RFSTDTC and RFENDTC in Demographics). \n Not all values of the codelist are allowable for this variable. See Section 4.4.7, Use of Relative Timing Variables.
A41: CEENRF | B41: End Relative to Reference Period | C41: Char | D41: 20 | E41: (STENRF) | F41: Derived | G41: 可有 | I41: SDTM | J41: =ROW()-13 -> 28 | K41: Describes the end of the event relative to the sponsor-defined reference period. The sponsor-defined reference period is a continuous period of time defined by a discrete starting point and a discrete ending point (represented by RFSTDTC and RFENDTC in Demographics). \n Not all values of the codelist are allowable for this variable. See Section 4.4.7, Use of Relative Timing Variables.
...

Sheet CM
A1: CM Domain Mapping Specifications
A2: 方案编号: | D2: =CONTENT!$B$3 -> XXXXX
A3: SDTM 版本: | D3: =CONTENT!$B$4 -> 3.4
A4: SDTM 数据集描述: | D4: =CONTENT!$B$12 -> Concomitant/Prior Medications
A5: SDTM 数据集结构: | D5: =CONTENT!$C$12 -> One record per recorded intervention occurrence or constant-dosing interval per subject
A6: 程序名称: | D6: =CONTENT!$D$12 -> cm.sas
A7: 常规观测分类: | D7: =CONTENT!$E$12 -> Interventions
A8: 数据来源: | D8: =CONTENT!$F$12 -> 0
A9: 关键变量: | D9: =CONTENT!$G$12 -> STUDYID, USUBJID, CMTRT, CMSTDTC
A10: 排序变量: | D10: =CONTENT!$H$12 -> STUDYID, USUBJID, CMTRT, CMSTDTC
A11: 提取规则: | D11: =CONTENT!$I$12 -> 0
A13: Variable Name | B13: Variable Label | C13: Type | D13: Length | E13: Controlled Terms, Codelist or Format | F13: Source | G13: Core | H13: Transformation definition | I13: Variable Type | J13: Variable Order | K13: CDISC Notes
A14: STUDYID | B14: Study Identifier | C14: Char | D14: 20 | F14: Assigned | G14: 必需 | I14: SDTM | J14: =ROW()-13 -> 1 | K14: Unique identifier for a study.
A15: DOMAIN | B15: Domain Abbreviation | C15: Char | D15: 2 | E15: CM | F15: Assigned | G15: 必需 | H15: CM | I15: SDTM | J15: =ROW()-13 -> 2 | K15: Two-character abbreviation for the domain.
A16: USUBJID | B16: Unique Subject Identifier | C16: Char | D16: 30 | F16: Derived | G16: 必需 | I16: SDTM | J16: =ROW()-13 -> 3 | K16: Identifier used to uniquely identify a subject across all studies for all applications or submissions involving the product.
A17: CMSEQ | B17: Sequence Number | C17: Num | F17: Derived | G17: 必需 | I17: SDTM | J17: =ROW()-13 -> 4 | K17: Sequence number to ensure uniqueness of subject records within a domain. May be any valid number.
A18: CMGRPID | B18: Group ID | C18: Char | D18: 25 | F18: CRF | G18: 可有 | I18: SDTM | J18: =ROW()-13 -> 5 | K18: Used to tie together a block of related records in a single domain for a subject.
A19: CMSPID | B19: Sponsor-Defined Identifier | C19: Char | D19: 25 | F19: CRF | G19: 可有 | I19: SDTM | J19: =ROW()-13 -> 6 | K19: Sponsor-defined reference number. Example: a number preprinted on the CRF as an explicit line identifier or record identifier defined in the sponsor's operational database. Example: line number on a concomitant medication page.
A20: CMTRT | B20: Reported Name of Drug, Med, or Therapy | C20: Char | D20: 200 | F20: CRF | G20: 必需 | I20: SDTM | J20: =ROW()-13 -> 7 | K20: Verbatim medication name that is either preprinted or collected on a CRF.
A21: CMMODIFY | B21: Modified Reported Name | C21: Char | D21: 200 | F21: Assigned | G21: 可有 | I21: SDTM | J21: =ROW()-13 -> 8 | K21: If CMTRT is modified to facilitate coding, then CMMODIFY will contain the modified text.
A22: CMDECOD | B22: Standardized Medication Name | C22: Char | D22: 200 | E22: * | F22: Assigned | G22: 可有 | I22: SDTM | J22: =ROW()-13 -> 9 | K22: Standardized or dictionary-derived text description of CMTRT or CMMODIFY. Equivalent to the generic drug name in WHO Drug. The sponsor is expected to provide the dictionary name and version used to map the terms utilizing the external codelist element in the Define-XML document. If an intervention term does not have a decode value in the dictionary, then CMDECOD will be left blank.
A23: CMCAT | B23: Category for Medication | C23: Char | D23: 100 | E23: * | F23: Assigned | G23: 可有 | I23: SDTM | J23: =ROW()-13 -> 10 | K23: Used to define a category of medications/treatment. Examples: "PRIOR", "CONCOMITANT", "ANTI-CANCER MEDICATION", "GENERAL CONMED".
A24: CMSCAT | B24: Subcategory for Medication | C24: Char | D24: 100 | E24: * | F24: Assigned | G24: 可有 | I24: SDTM | J24: =ROW()-13 -> 11 | K24: A further categorization of medications/treatment. Examples: "CHEMOTHERAPY", "HORMONAL THERAPY", "ALTERNATIVE THERAPY".
A25: CMPRESP | B25: CM Pre-specified | C25: Char | D25: 1 | E25: (NY) | F25: Assigned | G25: 可有 | I25: SDTM | J25: =ROW()-13 -> 12 | K25: Used to indicate whether ("Y"/null) information about the use of a specific medication was solicited on the CRF.
A26: CMOCCUR | B26: CM Occurrence | C26: Char | D26: 1 | E26: (NY) | F26: CRF | G26: 可有 | I26: SDTM | J26: =ROW()-13 -> 13 | K26: When the use of a specific medication is solicited. CMOCCUR is used to indicate whether ("Y"/"N") use of the medication occurred. Values are null for medications not specifically solicited.
A27: CMSTAT | B27: Completion Status | C27: Char | D27: 8 | E27: (ND) | F27: CRF | G27: 可有 | I27: SDTM | J27: =ROW()-13 -> 14 | K27: Used to indicate that a question about the occurrence of a prespecified intervention was not answered. Should be null or have a value of "NOT DONE".
A28: CMREASND | B28: Reason Medication Not Collected | C28: Char | D28: 200 | F28: CRF | G28: 可有 | I28: SDTM | J28: =ROW()-13 -> 15 | K28: Reason not done. Used in conjunction with CMSTAT when value is "NOT DONE".
A29: CMINDC | B29: Indication | C29: Char | D29: 100 | F29: CRF | G29: 可有 | I29: SDTM | J29: =ROW()-13 -> 16 | K29: Denotes why a medication was taken or administered. Examples: "NAUSEA", "HYPERTENSION".
A30: CMCLAS | B30: Medication Class | C30: Char | D30: 100 | E30: * | F30: Assigned | G30: 可有 | I30: SDTM | J30: =ROW()-13 -> 17 | K30: Drug class. May be obtained from coding. When coding to a single class, populate with class value. If using a dictionary and coding to multiple classes, then follow Section 4.2.8.3, Multiple Values for a Non-result Qualifier Variable, or omit CMCLAS.
A31: CMCLASCD | B31: Medication Class Code | C31: Char | D31: 100 | E31: * | F31: Assigned | G31: 可有 | I31: SDTM | J31: =ROW()-13 -> 18 | K31: Class code corresponding to CMCLAS. Drug class. May be obtained from coding. When coding to a single class, populate with class code. If using a dictionary and coding to multiple classes, then follow Section 4.2.8.3, Multiple Values for a Non-result Qualifier Variable, or omit CMCLASCD.
A32: CMDOSE | B32: Dose per Administration | C32: Num | F32: CRF | G32: 可有 | I32: SDTM | J32: =ROW()-13 -> 19 | K32: Amount of CMTRT given. Not populated when CMDOSTXT is populated.
A33: CMDOSTXT | B33: Dose Description | C33: Char | D33: 100 | F33: CRF | G33: 可有 | I33: SDTM | J33: =ROW()-13 -> 20 | K33: Dosing amounts or a range of dosing information collected in text form. Units may be stored in CMDOSU. Examples: "200-400", "15-20". Not populated when CMDOSE is populated.
A34: CMDOSU | B34: Dose Units | C34: Char | D34: 20 | E34: (UNIT) | F34: CRF | G34: 可有 | I34: SDTM | J34: =ROW()-13 -> 21 | K34: Units for CMDOSE, CMDOSTOT, or CMDOSTXT. Examples: "ng", "mg", "mg/kg".
A35: CMDOSFRM | B35: Dose Form | C35: Char | D35: 20 | E35: (FRM) | F35: CRF | G35: 可有 | I35: SDTM | J35: =ROW()-13 -> 22 | K35: Dose form for CMTRT. Examples: "TABLET", "LOTION".
A36: CMDOSFRQ | B36: Dosing Frequency per Interval | C36: Char | D36: 20 | E36: (FREQ) | F36: CRF | G36: 可有 | I36: SDTM | J36: =ROW()-13 -> 23 | K36: Usually expressed as the number of repeated administrations of CMDOSE within a specific time period. Examples: "BID" (twice daily), "Q12H" (every 12 hours).
A37: CMDOSTOT | B37: Total Daily Dose | C37: Num | F37: CRF | G37: 可有 | I37: SDTM | J37: =ROW()-13 -> 24 | K37: Total daily dose of CMTRT using the units in CMDOSU. Used when dosing is collected as total daily dose. Total dose over a period other than day could be recorded in a separate supplemental qualifier variable.
A38: CMDOSRGM | B38: Intended Dose Regimen | C38: Char | D38: 100 | F38: CRF | G38: 可有 | I38: SDTM | J38: =ROW()-13 -> 25 | K38: Text description of the (intended) schedule or regimen for the Intervention. Example: "TWO WEEKS ON, TWO WEEKS OFF".
A39: CMROUTE | B39: Route of Administration | C39: Char | D39: 20 | E39: (ROUTE) | F39: CRF | G39: 可有 | I39: SDTM | J39: =ROW()-13 -> 26 | K39: Route of administration for the intervention. Examples: "ORAL", "INTRAVENOUS".
A40: CMADJ | B40: Reason for Dose Adjustment | C40: Char | D40: 200 | F40: CRF | G40: 可有 | I40: SDTM | J40: =ROW()-13 -> 27 | K40: Describes reason or explanation of why a dose is adjusted. Examples: "ADVERSE EVENT", "INSUFFICIENT RESPONSE", "NON-MEDICAL REASON".
A41: CMRSDISC | B41: Reason the Intervention Was Discontinued | C41: Char | D41: 200 | F41: CRF | G41: 可有 | I41: SDTM | J41: =ROW()-13 -> 28 | K41: When dosing of a treatment is recorded over multiple successive records, this variable is applicable only for the (chronologically) last record for the treatment.
...

Sheet CO
A1: CO Domain Mapping Specifications
A2: 方案编号: | D2: =CONTENT!$B$3 -> XXXXX
A3: SDTM 版本: | D3: =CONTENT!$B$4 -> 3.4
A4: SDTM 数据集描述: | D4: =CONTENT!$B$13 -> Comments
A5: SDTM 数据集结构: | D5: =CONTENT!$C$13 -> One record per comment per subject
A6: 程序名称: | D6: =CONTENT!$D$13 -> co.sas
A7: 常规观测分类: | D7: =CONTENT!$E$13 -> Special Purpose
A8: 数据来源: | D8: =CONTENT!$F$13 -> 0
A9: 关键变量: | D9: =CONTENT!$G$13 -> STUDYID, USUBJID, IDVAR, COREF, CODTC
A10: 排序变量: | D10: =CONTENT!$H$13 -> STUDYID, USUBJID, IDVAR, COREF, CODTC
A11: 提取规则: | D11: =CONTENT!$I$13 -> 0
A13: Variable Name | B13: Variable Label | C13: Type | D13: Length | E13: Controlled Terms, Codelist or Format | F13: Source | G13: Core | H13: Transformation definition | I13: Variable Type | J13: Variable Order | K13: CDISC Notes
A14: STUDYID | B14: Study Identifier | C14: Char | D14: 20 | F14: Assigned | G14: 必需 | I14: SDTM | J14: =ROW()-13 -> 1 | K14: Unique identifier for a study.
A15: DOMAIN | B15: Domain Abbreviation | C15: Char | D15: 2 | E15: CO | F15: Assigned | G15: 必需 | H15: CO | I15: SDTM | J15: =ROW()-13 -> 2 | K15: Two-character abbreviation for the domain.
A16: RDOMAIN | B16: Related Domain Abbreviation | C16: Char | D16: 2 | E16: (RODOMAIN) | F16: Assigned | G16: 可有 | I16: SDTM | J16: =ROW()-13 -> 3 | K16: Two-character abbreviation for the domain of the parent record(s). Null for comments collected on a general comments or additional information CRF page.
A17: USUBJID | B17: Unique Subject Identifier | C17: Char | D17: 30 | F17: Derived | G17: 必需 | I17: SDTM | J17: =ROW()-13 -> 4 | K17: Identifier used to uniquely identify a subject across all studies for all applications or submissions involving the product.
A18: COSEQ | B18: Sequence Number | C18: Num | F18: Derived | G18: 必需 | I18: SDTM | J18: =ROW()-13 -> 5 | K18: Sequence Number given to ensure uniqueness of subject records within a domain. May be any valid number.
A19: IDVAR | B19: Identifying Variable | C19: Char | D19: 25 | E19: * | F19: Assigned | G19: 可有 | I19: SDTM | J19: =ROW()-13 -> 6 | K19: Identifying variable in the parent dataset that identifies the record(s) to which the comment applies. Examples AESEQ or CMGRPID. Used only when individual comments are related to domain records. Null for comments collected on separate CRFs.
A20: IDVARVAL | B20: Identifying Variable Value | C20: Char | D20: 40 | F20: Assigned | G20: 可有 | I20: SDTM | J20: =ROW()-13 -> 7 | K20: Value of identifying variable of the parent record(s). Used only when individual comments are related to domain records. Null for comments collected on separate CRFs.
A21: COREF | B21: Comment Reference | C21: Char | D21: 200 | F21: Derived | G21: 可有 | I21: SDTM | J21: =ROW()-13 -> 8 | K21: Sponsor-defined reference associated with the comment. May be the CRF page number (e.g., 650), or a module name (e.g., DEMOG), or a combination of information that identifies the reference (e.g. 650-VITALS-VISIT 2).
A22: COVAL | B22: Comment | C22: Char | D22: 200 | F22: CRF | G22: 必需 | I22: SDTM | J22: =ROW()-13 -> 9 | K22: The text of the comment. Text over 200 characters can be added to additional columns COVAL1-COVALn. See Assumption 3.
A23: COEVAL | B23: Evaluator | C23: Char | D23: 100 | E23: (EVAL) | F23: Assigned | G23: 可有 | I23: SDTM | J23: =ROW()-13 -> 10 | K23: Role of the person who provided the evaluation. Used only for results that are subjective (e.g., assigned by a person or a group). Example: "INVESTIGATOR".
A24: COEVALID | B24: Evaluator Identifier | C24: Char | D24: 30 | E24: (MEDEVAL) | F24: Assigned | G24: 可有 | I24: SDTM | J24: =ROW()-13 -> 11 | K24: Used to distinguish multiple evaluators with the same role recorded in --EVAL. Examples: "RADIOLOGIST", "RADIOLOGIST 1", "RADIOLOGIST 2".
A25: CODTC | B25: Date/Time of Comment | C25: Char | D25: 20 | E25: ISO 8601 | F25: CRF | G25: 可有 | I25: SDTM | J25: =ROW()-13 -> 12 | K25: Date/time of comment on dedicated comment form. Should be null if this is a child record of another domain or if comment date was not collected.
A26: CODY | B26: Study Day of Comment | C26: Num | F26: Derived | G26: 可有 | I26: SDTM | J26: =ROW()-13 -> 13 | K26: Study day of the comment, in integer days. The algorithm for calculations must be relative to the sponsor-defined RFSTDTC variable in the Demographics (DM) domain.
A30: CONTENT

Sheet CP
A1: CP Domain Mapping Specifications
A2: 方案编号: | D2: =CONTENT!$B$3 -> XXXXX
A3: SDTM 版本: | D3: =CONTENT!$B$4 -> 3.4
A4: SDTM 数据集描述: | D4: =CONTENT!$B$14 -> Cell Phenotype Findings
A5: SDTM 数据集结构: | D5: =CONTENT!$C$14 -> One record per test per specimen per timepoint per visit per subject
A6: 程序名称: | D6: =CONTENT!$D$14 -> cp.sas
A7: 常规观测分类: | D7: =CONTENT!$E$14 -> Findings
A8: 数据来源: | D8: =CONTENT!$F$14 -> 0
A9: 关键变量: | D9: =CONTENT!$G$14 -> STUDYID, USUBJID, CPTESTCD, CPSPEC, VISITNUM, CPTPTREF, CPTPTNUM
A10: 排序变量: | D10: =CONTENT!$H$14 -> STUDYID, USUBJID, CPTESTCD, CPSPEC, VISITNUM, CPTPTREF, CPTPTNUM
A11: 提取规则: | D11: =CONTENT!$I$14 -> 0
A13: Variable Name | B13: Variable Label | C13: Type | D13: Length | E13: Controlled Terms, Codelist or Format | F13: Source | G13: Core | H13: Transformation definition | I13: Variable Type | J13: Variable Order | K13: CDISC Notes
A14: STUDYID | B14: Study Identifier | C14: Char | D14: 20 | F14: Assigned | G14: 必需 | I14: SDTM | J14: 1 | K14: Unique identifier for a study.
A15: DOMAIN | B15: Domain Abbreviation | C15: Char | D15: 2 | E15: CP | F15: Assigned | G15: 必需 | H15: CP | I15: SDTM | J15: 2 | K15: Two-character abbreviation for the domain.
A16: USUBJID | B16: Unique Subject Identifier | C16: Char | D16: 30 | F16: Derived | G16: 必需 | I16: SDTM | J16: 3 | K16: Identifier used to uniquely identify a subject across all studies for all applications or submissions involving the product.
A17: CPSEQ | B17: Sequence Number | C17: Num | F17: Derived | G17: 必需 | I17: SDTM | J17: 4 | K17: Sequence number to ensure uniqueness of subject records within a domain. May be any valid number.
A18: CPGRPID | B18: Group ID | C18: Char | D18: 25 | F18: CRF | G18: 可有 | I18: SDTM | J18: 5 | K18: Used to tie together a block of related records in a single domain for a subject.
A19: CPREFID | B19: Reference ID | C19: Char | D19: 25 | F19: CRF | G19: 可有 | I19: SDTM | J19: 6 | K19: Internal or external specimen identifier.
A20: CPSPID | B20: Sponsor-Defined Identifier | C20: Char | D20: 25 | F20: CRF | G20: 可有 | I20: SDTM | J20: 7 | K20: Sponsor-defined reference number. May be preprinted on the CRF as an explicit line identifier or defined in the sponsor's operational database. Example: Line number on the lab page.
A21: CPLNKID | B21: Link ID | C21: Char | D21: 25 | F21: CRF | G21: 可有 | I21: SDTM | J21: 8 | K21: Identifier used to link related records across domains. This may be a one-to-one or a one-to-many relationship.
A22: CPLNKGRP | B22: Link Group ID | C22: Char | D22: 25 | F22: CRF | G22: 可有 | I22: SDTM | J22: 9 | K22: Identifier used to link related records across domains. This will usually be a many-to-one relationship.
A23: CPTESTCD | B23: Test or Examination Short Name | C23: Char | D23: 8 | E23: (CPTESTCD) | F23: Assigned | G23: 必需 | I23: SDTM | J23: 10 | K23: Short name of the measurement, test, or examination described in CPTEST. It can be used as a column name when converting a dataset from a vertical to a horizontal format. The value in CPTESTCD cannot be longer than 8 characters, nor can it start with a number (e.g., "1TEST" is not valid). CPTESTCD cannot contain characters other than letters, numbers, or underscores. Examples: "MONO", "MNS".
A24: CPTEST | B24: Name of Measurement, Test or Examination | C24: Char | D24: 40 | E24: (CPTEST) | F24: Assigned | G24: 必需 | I24: SDTM | J24: 11 | K24: Long name for CPTESTCD. For cell phenotyping, the name (often abbreviated) of the cell population, as it is generally accepted by the scientific community, is populated (rather than a colloquial designation based on a primary marker, e.g., TLym Help rather than CD4). When the test is for a sublineage which can only be identified by specifying additional markers (i.e., has not been given a name) or which is further restricted to a subpopulation based on a particular cell state (e.g., activated, proliferating, apoptotic), the Sublineage Marker String (CPSBMRKS), Cell State (CPCELSTA), and Cell State Marker String (CPCSMRKS) variables are additionally populated and the value in CPTEST is suffixed with "Sub" to denote that it is a subset of the population identified in CPTEST (e.g., Monocytes Sub). \n The value in CPTEST cannot be longer than 40 characters.
A25: CPSBMRKS | B25: Sublineage Marker String | C25: Char | D25: 100 | F25: Assigned | G25: 可有 | I25: SDTM | J25: 12 | K25: Used to further subset the cell population identified in CPTEST based on the use of additional marker(s) that define a sublineage. The value in CPSBMRKS is used in combination with values in CPTEST and CPCELSTA to fully describe the cell population being measured. As such, it is an essential component of the full test name. \n For example, three unnamed sublineages of monocytes have been identified as: CCR2+CD16-, CCR2-CD16+, and CCR2+CD16+. Whereas the entire monocyte cell population can be defined as CD14+ cells, the additional CCR2 and CD16 markers are used to differentiate one sublineage from another. As none of these sublineages have been given names, they are only known by the CCR2 and CD16 marker combinations. By associating the CPTEST value of "Monocytes Sub" with, for example, a value of "CCR2+CD16-" in CPSBMRKS, the full test is defined to be the CCR2+CD16- monocyte subpopulation.
A26: CPCELSTA | B26: Cell State | C26: Char | D26: 40 | E26: (CELSTATE) | F26: Assigned | G26: 可有 | I26: SDTM | J26: 13 | K26: A textual description of a subset of the cell population identified in CPTEST based on a particular functional and/or biological state (e.g., "ACTIVATED", "PROLIFERATING", "SENESCENT"). When populated, the values in CPCELSTA and CPSMRKS, in combination with the values in CPTEST and CPSBMRKS, fully describe the cell population being measured.
